<?xml version="1.0" ?>
<!-- =================================================================================== -->
<!-- |    This document was autogenerated by xacro from pluto.xacro                    | -->
<!-- |    EDITING THIS FILE BY HAND IS NOT RECOMMENDED                                 | -->
<!-- =================================================================================== -->
<robot name="pluto">
  <link name="base_footprint">
    <inertial>
      <mass value="10"/>
      <inertia ixx="1.6666666666666667e-06" ixy="0.0" ixz="0.0" iyy="1.6666666666666667e-06" iyz="0.0" izz="1.6666666666666667e-06"/>
    </inertial>
    <visual>
      <origin rpy="0 0 0" xyz="0 0 0"/>
      <geometry>
        <box size="0.001 0.001 0.001"/>
      </geometry>
    </visual>
  </link>
  
  <link name="base_link">
    <inertial>
      <mass value="50"/>
      <inertia ixx="2.1505333333333336" ixy="0.0" ixz="0.0" iyy="2.1505333333333336" iyz="0.0" izz="2.1505333333333336"/>
    </inertial>
    <visual>
      <origin rpy="0 0 0" xyz="-0.015 -0.00275 0"/>
      <geometry>
        <box size=".508 .508 .508"/>
      </geometry>
    </visual>
    <collision>
      <origin rpy="0 0 0" xyz="-0.015 -0.00275 0"/>
      <geometry>
        <box size=".508 .508 .508"/>
      </geometry>
    </collision>
  </link>
  <joint name="base_link_joint" type="fixed">
    <origin rpy="0 0 0" xyz="0 0 0"/>
    <parent link="base_footprint"/>
    <child link="base_link"/>
  </joint>
  
  <link name="torso">
    <inertial>
      <mass value="20"/>
      <inertia ixx="0.4010744666666667" ixy="0.0" ixz="0.0" iyy="0.45591306666666664" iyz="0.0" izz="0.16021473333333336"/>
    </inertial>
    <visual>
      <origin rpy="0 0 0" xyz="0 0 0.4826"/>
      <geometry>
        <box size="0.1778 0.254 0.4572"/>
      </geometry>
    </visual>
    <collision>
      <origin rpy="0 0 0" xyz="0 0 0.4826"/>
      <geometry>
        <box size="0.1778 0.254 0.4572"/>
      </geometry>
    </collision>
  </link>
  <joint name="torso_joint" type="revolute">
    <origin rpy="0 0 0" xyz="0 0 0"/>
    <axis rpy="0 0 0" xyz="0 0 1"/>
    <parent link="base_link"/>
    <child link="torso"/>
    <origin rpy="-0 0 0" xyz="0.0 0.0 0.0"/>
    <limit effort="1.0" lower="0" upper="3.14159" velocity="1.0"/>
  </joint>
  
  <link name="right_shoulder">
    <visual>
      <origin rpy="0 0 0" xyz="0 0 0"/>
      <geometry>
        <cylinder length="0.0381" radius="0.0889" />
      </geometry>
    </visual>
    <collision>
      <origin rpy="0 0 0" xyz="0 0 0"/>
      <geometry>
        <cylinder length="0.0381" radius="0.0889" />
      </geometry>
      <surface>
        <friction>
          <ode>
            <mu>0.01</mu>
            <mu2>0.01</mu2>
          </ode>
        </friction>
      </surface>
    </collision>
    <inertial>
      <mass value="3"/>
      <inertia ixx="0.0030645100000000008" ixy="0" ixz="0" iyy="0.0030645100000000008" iyz="0" izz="0.0021774150000000003"/>
    </inertial>
  </link>
  <joint name="right_shoulder_joint" type="revolute">
    <axis rpy="0 0 0" xyz="0 0 1"/>
    <parent link="torso"/>
    <child link="right_shoulder"/>
    <!--origin rpy="0 0 0" xyz="0 -0.055 0.372"/-->
    <origin rpy="-1.57 0 0" xyz="0.0 -0.20955 0.635"/>
    <limit effort="1.0" lower="0" upper="6.28318" velocity="1.0"/>
  </joint>
  
  <link name="right_upper_arm_bottom">
    <visual>
      <origin rpy="0 0 0" xyz="0 0 0"/>
      <geometry>
        <cylinder length="0.054" radius="0.03175"/>
      </geometry>
    </visual>
    <collision>
      <origin rpy="0 0 0" xyz="0 0 0"/>
      <geometry>
        <cylinder length="0.054" radius="0.03175"/>
      </geometry>
    </collision>
    <inertial>
      <mass value="0.5"/>
      <inertia ixx="0.002814174479166667" ixy="0" ixz="0" iyy="0.002814174479166667" iyz="0" izz="0.000252015625"/>
    </inertial>
  </link>
  <joint name="right_upper_arm_bottom_joint" type="revolute">
    <axis rpy="0 0 0" xyz="0 1 0"/>
    <parent link="right_shoulder"/>
    <child link="right_upper_arm_bottom"/>
    <!--origin rpy="0 0 0" xyz="0 -0.0225 0"/-->
    <origin rpy="1.5707963267948966 0 0" xyz="0 -0.0 -0.081"/>
    <limit effort="1.0" lower="0" upper="3.14159" velocity="1.0"/>
  </joint>
  
  <link name="right_upper_arm_top">
    <visual>
      <origin rpy="0 0 0" xyz="0 0 0"/>
      <geometry>
        <cylinder length="0.2" radius="0.03175"/>
      </geometry>
    </visual>
    <collision>
      <origin rpy="0 0 0" xyz="0 0 0"/>
      <geometry>
        <cylinder length="0.2" radius="0.03175"/>
      </geometry>
    </collision>
    <inertial>
      <mass value="4"/>
      <inertia ixx="0.022513395833333335" ixy="0" ixz="0" iyy="0.022513395833333335" iyz="0" izz="0.002016125"/>
    </inertial>
  </link>
  <joint name="right_upper_arm_top_joint" type="revolute">
    <axis rpy="0 0 0" xyz="0 0 1"/>
    <parent link="right_upper_arm_bottom"/>
    <child link="right_upper_arm_top"/>
    <origin rpy="0 0 0" xyz="0 0 -0.13175"/>
    <limit effort="1.0" lower="0" upper="6.28318" velocity="1.0"/>
  </joint>
  
  <link name="right_forearm_bottom">
    <visual>
      <origin rpy="0 0 0" xyz="0 0 0"/>
      <geometry>
        <cylinder length="0.2032" radius="0.03175"/>
      </geometry>
    </visual>
    <collision>
      <origin rpy="0 0 0" xyz="0 0 0"/>
      <geometry>
        <cylinder length="0.2032" radius="0.03175"/>
      </geometry>
    </collision>
    <inertial>
      <mass value="0.5"/>
      <inertia ixx="0.0005561144791666667" ixy="0" ixz="0" iyy="0.0005561144791666667" iyz="0" izz="0.000252015625"/>
    </inertial>
  </link>
  <joint name="right_forearm_bottom_joint" type="revolute">
    <axis rpy="0 0 0" xyz="0 1 0"/>
    <parent link="right_upper_arm_top"/>
    <child link="right_forearm_bottom"/>
    <origin rpy="0 -1.5707963267948966 0" xyz="0.0908 0 -0.155"/>
    <limit effort="1.0" lower="0" upper="3.14159" velocity="1.0"/>
    <dyanamics damping="10.0" friction="10.0"/>
  </joint>
  <!-- 0 1.5707963267948966 0 -->
 <link name="right_palm">
    <inertial>
      <mass value="0.2"/>
      <inertia ixx="0.000419354" ixy="0.0" ixz="0.0" iyy="0.00080645" iyz="0.0" izz="0.000419354"/>
    </inertial>
    <visual>
      <origin rpy="0 0 0" xyz="0 0 0"/>
      <geometry>
        <box size="0.05 0.02 0.001"/>
      </geometry>
    </visual>
    <collision>
      <origin rpy="0 0 0" xyz="0 0 0"/>
      <geometry>
        <box size="0.05 0.03 0.01"/>
      </geometry>
    </collision>
  </link>
  <joint name="right_palm_joint" type="revolute">
    <origin rpy="0 1.5707963267948966 1.5707963267948966" xyz="-0.0 -0.0 -0.13"/>
    <axis rpy="0 0 0" xyz="1 0 0"/>
    <parent link="right_forearm_bottom"/>
    <child link="right_palm"/>
    <limit effort="1.0" lower="0" upper="3.14159" velocity="1.0"/>
  </joint>
</robot>

