<?xml version="1.0"?>
<robot xmlns:xacro="http://www.ros.org/wiki/xacro" name="pluto">

  <xacro:property name="base_width" value="0.508"/>
  <xacro:property name="base_length" value="0.508"/>
  <xacro:property name="base_height" value="0.508"/>
  <xacro:property name="wheel_radius" value="0.1016"/>
  <xacro:property name="base_wheel_gap" value="0.0125"/>
  <xacro:property name="wheel_separation" value="0.5205"/>
  <xacro:property name="wheel_joint_offset" value="0.02"/>
  <xacro:property name="caster_wheel_radius" value="0.0125"/>
  
  <xacro:macro name="box_inertia" params="m w h d">
    <inertial>
      <mass value="${m}"/>
      <inertia ixx="${m / 12.0 * (d*d + h*h)}" ixy="0.0" ixz="0.0" iyy="${m / 12.0 * (w*w + h*h)}" iyz="0.0" izz="${m / 12.0 * (w*w + d*d)}"/>
    </inertial>
  </xacro:macro>
  
  <xacro:macro name="cylinder_inertia" params="m r h">
    <inertial>
      <mass value="${m}"/>
      <inertia ixx="${m*(3*r*r+h*h)/12}" ixy = "0" ixz = "0" iyy="${m*(3*r*r+h*h)/12}" iyz = "0" izz="${m*r*r/2}"/> 
    </inertial>
  </xacro:macro>
  
  <link name="base_footprint">
    <xacro:box_inertia m="10" w="0.001" h="0.001" d="0.001"/>
    <visual>
        <origin xyz="0 0 0" rpy="0 0 0" />
        <geometry>
            <box size="0.001 0.001 0.001" />
        </geometry>
    </visual>
  </link>
  
  <link name="base_link">
    <xacro:box_inertia m="50" w="${base_length}" h="${base_width}" d="${base_height}"/>
    <visual>
      <origin xyz="-0.015 -0.00275 0" rpy="0 0 0" />
      <geometry>
        <!--box size="${base_length} ${base_width} ${base_height}" /-->
        <mesh filename="package://pluto/models/Chassis.dae" scale="1 1 1"/>
      </geometry>
    </visual>
    <collision>
      <origin xyz="-0.015 -0.00275 0" rpy="0 0 0" />
      <geometry>
        <!--box size="${base_length} ${base_width} ${base_height}"/-->
        <mesh filename="package://pluto/models/Chassis.dae" scale="1 1 1"/>
      </geometry>
    </collision>
  </link>
 
  <joint name="base_link_joint" type="fixed">
    <origin xyz="0 0 0" rpy="0 0 0" />
    <parent link="base_footprint"/>
    <child link="base_link" />
  </joint>
  
  <link name="torso">
    <xacro:box_inertia m="20" w="0.254" h="0.4572" d="0.1778"/>
    <visual>
      <origin xyz="0 0 0.32" rpy="0 0 0" />
      <geometry>
        <mesh filename="package://pluto/models/Torso.dae" scale="1 1 1"/>
      </geometry>
    </visual>
    <collision>
      <origin xyz="0 0 0.32" rpy="0 0 0" />
      <geometry>
        <mesh filename="package://pluto/models/Torso.dae" scale="1 1 1"/>
      </geometry>
    </collision>
  </link>
  
  <joint name="torso_joint" type="revolute">
    <origin xyz="0 0 0" rpy="0 0 0" />
    <axis xyz="0 0 1" rpy="0 0 0" />
    <parent link="base_link"/>
    <child link="torso" />
    <limit effort="1.0" lower="-1.79769e+308" upper="1.79769e+308" velocity="1.0"/>
  </joint>
  
  <xacro:macro name="shoulder" params="prefix reflect flip">
    <link name="${prefix}_shoulder">
      <visual>
        <origin xyz="0 0 0" rpy="${flip} 0 0"/>
        <geometry>
          <mesh filename="package://pluto/models/Shoulder.dae" scale="1 1 1"/>
        </geometry>
      </visual>
      <collision>
        <origin xyz="0 0 0" rpy="${flip} 0 0"/>
        <geometry>        	
          <mesh filename="package://pluto/models/Shoulder.dae" scale="1 1 1"/>
        </geometry>
        <surface>
         <friction>
          <ode>
            <mu>0.01</mu>
            <mu2>0.01</mu2>
          </ode>
         </friction>
        </surface>
      </collision>
      <xacro:cylinder_inertia m="3" r="0.0381" h="0.0889"/>
    </link>
 
    <joint name="${prefix}_shoulder_joint" type="revolute">
      <axis xyz="0 1 0" rpy="0 0 0" />
      <parent link="torso"/>
      <child link="${prefix}_shoulder"/>
      <origin xyz="0 ${(0.055 * reflect)} 0.372" rpy="0 0 0" />
      <limit effort="30.0" lower="-1.79769e+308" upper="1.79769e+308" velocity="1.0"/>
    </joint>
  </xacro:macro>
 
  <xacro:shoulder prefix="left" reflect="1" flip= "${(pi)}"/>
  
  <xacro:macro name="upper_arm_bottom" params="prefix reflect flip">
   <link name="${prefix}_upper_arm_bottom">
     <visual>
       <origin xyz="0 0 0" rpy="0 0 ${flip}"/>
       <geometry>
         <mesh filename="package://pluto/models/UpperArmBottom.dae" scale="1 1 1"/>
       </geometry>
     </visual>
     <collision>
       <origin xyz="0 0 0" rpy="${flip} 0 0"/>
       <geometry>        	
         <mesh filename="package://pluto/models/UpperArmBottom.dae" scale="1 1 1"/>
       </geometry>
       <surface>
         <friction>
          <ode>
            <mu>0.01</mu>
            <mu2>0.01</mu2>
          </ode>
         </friction>
       </surface>
     </collision>
     <xacro:cylinder_inertia m="0.5" r="0.03175" h="0.254"/>
   </link>
 
   <joint name="${prefix}_upper_arm_bottom_joint" type="revolute">
     <axis xyz="1 0 0" rpy="0 0 0" />
     <parent link="${prefix}_shoulder"/>
     <child link="${prefix}_upper_arm_bottom"/>
     <origin xyz="0 ${(0.0225 * reflect)} 0" rpy="0 0 0" />
     <limit effort="30.0" lower="-1.79769e+308" upper="1.79769e+308" velocity="1.0"/>
   </joint>
  </xacro:macro>
 
  <xacro:upper_arm_bottom prefix="left" reflect="1" flip= "${(pi)}"/>
  
  <xacro:macro name="upper_arm_top" params="prefix reflect flip">
   <link name="${prefix}_upper_arm_top">
     <visual>
       <origin xyz="0 0 0" rpy="0 0 ${flip}"/>
       <geometry>
         <mesh filename="package://pluto/models/UpperArmTop.dae" scale="1 1 1"/>
       </geometry>
     </visual>
     <collision>
       <origin xyz="0 0 0" rpy="${flip} 0 0"/>
       <geometry>        	
         <mesh filename="package://pluto/models/UpperArmTop.dae" scale="1 1 1"/>
       </geometry>
       <surface>
         <friction>
          <ode>
            <mu>0.01</mu>
            <mu2>0.01</mu2>
          </ode>
         </friction>
       </surface>
     </collision>
     <xacro:cylinder_inertia m="4" r="0.03175" h="0.254"/>
   </link>
 
   <joint name="${prefix}_upper_arm_top_joint" type="revolute">
     <axis xyz="0 0 1" rpy="0 0 0" />
     <parent link="${prefix}_upper_arm_bottom"/>
     <child link="${prefix}_upper_arm_top"/>
     <origin xyz="0 0 -0.03125" rpy="0 0 0" />
     <limit effort="1.0" lower="-1.79769e+308" upper="1.79769e+308" velocity="1.0"/>
   </joint>
  </xacro:macro>
 
  <xacro:upper_arm_top prefix="left" reflect="1" flip= "${(pi)}"/>
  
  <xacro:macro name="forearm_bottom" params="prefix reflect flip">
   <link name="${prefix}_forearm_bottom">
     <visual>
       <origin xyz="0 0 0" rpy="${flip} 0 0"/>
       <geometry>
         <mesh filename="package://pluto/models/ForearmBottom.dae" scale="1 1 1"/>
       </geometry>
     </visual>
     <collision>
       <origin xyz="0 0 0" rpy="${flip} 0 0"/>
       <geometry>        	
         <mesh filename="package://pluto/models/ForearmBottom.dae" scale="1 1 1"/>
       </geometry>
       <!--surface>
         <friction>
          <ode>
            <mu>1000.0</mu>
            <mu2>1000.0</mu2>
          </ode>
         </friction>
       </surface-->
     </collision>
     <xacro:cylinder_inertia m="0.5" r="0.03175" h="0.1016"/>
   </link>
 
   <joint name="${prefix}_forearm_bottom_joint" type="revolute">
     <axis xyz="0 1 0" rpy="0 0 0" />
     <parent link="${prefix}_upper_arm_top"/>
     <child link="${prefix}_forearm_bottom"/>
     <origin xyz="0 ${(0 * reflect)} -0.07625" rpy="0 ${pi/2} 0" />
     <limit effort="10.0" lower="-1.79769e+308" upper="1.79769e+308" velocity="1.0"/>
     <dyanamics damping="10.0" friction="10.0" />
   </joint>
  </xacro:macro>
 
  <xacro:forearm_bottom prefix="left" reflect="1" flip= "${(pi)}"/>

  <xacro:macro name="forearm_top" params="prefix reflect flip">
   <link name="${prefix}_forearm_top">
     <visual>
       <origin xyz="0 0 0" rpy="${flip} 0 0"/>
       <geometry>
         <mesh filename="package://pluto/models/ForearmTop.dae" scale="1 1 1"/>
       </geometry>
     </visual>
     <collision>
       <origin xyz="0 0 0" rpy="${flip} 0 0"/>
       <geometry>        	
         <mesh filename="package://pluto/models/ForearmTop.dae" scale="1 1 1"/>
       </geometry>
       <!--surface>
         <friction>
          <ode>
            <mu>1.0</mu>
            <mu2>1.0</mu2>
          </ode>
         </friction>
       </surface-->
     </collision>
     <xacro:cylinder_inertia m="0.4" r="0.03175" h="0.1016"/>
   </link>
 
   <joint name="${prefix}_forearm_top_joint" type="revolute">
     <axis xyz="1 0 0" rpy="0 0 0" />
     <parent link="${prefix}_forearm_bottom"/>
     <child link="${prefix}_forearm_top"/>
     <origin xyz="0.029 ${(0 * reflect)} 0" rpy="0 0 0" />
     <limit effort="1.0" lower="-1.79769e+308" upper="1.79769e+308" velocity="1.0"/>
   </joint>
  </xacro:macro>
 
  <xacro:forearm_top prefix="left" reflect="1" flip= "${(pi)}"/>
</robot>
