<sdf version='1.7'>
  <world name='default'>
    <light name='sun' type='directional'>
      <cast_shadows>1</cast_shadows>
      <pose>0 0 10 0 -0 0</pose>
      <diffuse>0.8 0.8 0.8 1</diffuse>
      <specular>0.2 0.2 0.2 1</specular>
      <attenuation>
        <range>1000</range>
        <constant>0.9</constant>
        <linear>0.01</linear>
        <quadratic>0.001</quadratic>
      </attenuation>
      <direction>-0.5 0.1 -0.9</direction>
      <spot>
        <inner_angle>0</inner_angle>
        <outer_angle>0</outer_angle>
        <falloff>0</falloff>
      </spot>
    </light>
    <model name='ground_plane'>
      <static>1</static>
      <link name='link'>
        <collision name='collision'>
          <geometry>
            <plane>
              <normal>0 0 1</normal>
              <size>100 100</size>
            </plane>
          </geometry>
          <surface>
            <contact>
              <collide_bitmask>65535</collide_bitmask>
              <ode/>
            </contact>
            <friction>
              <ode>
                <mu>100</mu>
                <mu2>50</mu2>
              </ode>
              <torsional>
                <ode/>
              </torsional>
            </friction>
            <bounce/>
          </surface>
          <max_contacts>10</max_contacts>
        </collision>
        <visual name='visual'>
          <cast_shadows>0</cast_shadows>
          <geometry>
            <plane>
              <normal>0 0 1</normal>
              <size>100 100</size>
            </plane>
          </geometry>
          <material>
            <script>
              <uri>file://media/materials/scripts/gazebo.material</uri>
              <name>Gazebo/Grey</name>
            </script>
          </material>
        </visual>
        <self_collide>0</self_collide>
        <enable_wind>0</enable_wind>
        <kinematic>0</kinematic>
      </link>
    </model>
    <gravity>0 0 -9.8</gravity>
    <magnetic_field>6e-06 2.3e-05 -4.2e-05</magnetic_field>
    <atmosphere type='adiabatic'/>
    <physics type='ode'>
      <max_step_size>0.001</max_step_size>
      <real_time_factor>1</real_time_factor>
      <real_time_update_rate>1000</real_time_update_rate>
    </physics>
    <scene>
      <ambient>0.4 0.4 0.4 1</ambient>
      <background>0.7 0.7 0.7 1</background>
      <shadows>1</shadows>
    </scene>
    <wind/>
    <spherical_coordinates>
      <surface_model>EARTH_WGS84</surface_model>
      <latitude_deg>0</latitude_deg>
      <longitude_deg>0</longitude_deg>
      <elevation>0</elevation>
      <heading_deg>0</heading_deg>
    </spherical_coordinates>
    <model name='pluto.xacro'>
      <link name='base_footprint'>
        <inertial>
          <pose>0.000476 0 0.025054 0 -0 0</pose>
          <mass>4.201</mass>
          <inertia>
            <ixx>0.135782</ixx>
            <ixy>0</ixy>
            <ixz>-0.000999893</ixz>
            <iyy>0.141186</iyy>
            <iyz>0</iyz>
            <izz>0.0591647</izz>
          </inertia>
        </inertial>
        <collision name='base_footprint_fixed_joint_lump__base_link_collision'>
          <pose>-0.015 -0.00275 0 0 -0 0</pose>
          <geometry>
            <mesh>
              <scale>1 1 1</scale>
              <uri>/home/tuttu/ros_ws/src/pluto/models/Chassis.dae</uri>
            </mesh>
          </geometry>
          <max_contacts>10</max_contacts>
          <surface>
            <contact>
              <ode/>
            </contact>
            <bounce/>
            <friction>
              <torsional>
                <ode/>
              </torsional>
              <ode/>
            </friction>
          </surface>
        </collision>
        <collision name='base_footprint_fixed_joint_lump__imu_link_collision_1'>
          <pose>0 0 0.25 0 -0 0</pose>
          <geometry>
            <box>
              <size>0.001 0.001 0.001</size>
            </box>
          </geometry>
          <max_contacts>10</max_contacts>
          <surface>
            <contact>
              <ode/>
            </contact>
            <bounce/>
            <friction>
              <torsional>
                <ode/>
              </torsional>
              <ode/>
            </friction>
          </surface>
        </collision>
        <collision name='base_footprint_fixed_joint_lump__sensor_laser_collision_2'>
          <pose>0.01 0 0.525 0 -0 0</pose>
          <geometry>
            <box>
              <size>0.02 0.02 0.02</size>
            </box>
          </geometry>
          <surface>
            <contact>
              <ode/>
            </contact>
            <friction>
              <ode/>
              <torsional>
                <ode/>
              </torsional>
            </friction>
            <bounce/>
          </surface>
          <max_contacts>10</max_contacts>
        </collision>
        <collision name='base_footprint_fixed_joint_lump__torso_collision_3'>
          <pose>0 0 0.32 0 -0 0</pose>
          <geometry>
            <mesh>
              <scale>1 1 1</scale>
              <uri>/home/tuttu/ros_ws/src/pluto/models/Torso.dae</uri>
            </mesh>
          </geometry>
          <max_contacts>10</max_contacts>
          <surface>
            <contact>
              <ode/>
            </contact>
            <bounce/>
            <friction>
              <torsional>
                <ode/>
              </torsional>
              <ode/>
            </friction>
          </surface>
        </collision>
        <visual name='base_footprint_visual'>
          <pose>0 0 0 0 -0 0</pose>
          <geometry>
            <box>
              <size>0.001 0.001 0.001</size>
            </box>
          </geometry>
        </visual>
        <visual name='base_footprint_fixed_joint_lump__base_link_visual_1'>
          <pose>-0.015 -0.00275 0 0 -0 0</pose>
          <geometry>
            <mesh>
              <scale>1 1 1</scale>
              <uri>/home/tuttu/ros_ws/src/pluto/models/Chassis.dae</uri>
            </mesh>
          </geometry>
        </visual>
        <visual name='base_footprint_fixed_joint_lump__imu_link_visual_2'>
          <pose>0 0 0.25 0 -0 0</pose>
          <geometry>
            <box>
              <size>0.001 0.001 0.001</size>
            </box>
          </geometry>
        </visual>
        <visual name='base_footprint_fixed_joint_lump__sensor_laser_visual_3'>
          <pose>0.01 0 0.525 0 -0 0</pose>
          <geometry>
            <box>
              <size>0.02 0.02 0.02</size>
            </box>
          </geometry>
        </visual>
        <visual name='base_footprint_fixed_joint_lump__torso_visual_4'>
          <pose>0 0 0.32 0 -0 0</pose>
          <geometry>
            <mesh>
              <scale>1 1 1</scale>
              <uri>/home/tuttu/ros_ws/src/pluto/models/Torso.dae</uri>
            </mesh>
          </geometry>
        </visual>
        <gravity>1</gravity>
        <velocity_decay/>
        <sensor name='head_hokuyo_sensor' type='ray'>
          <visualize>1</visualize>
          <update_rate>20</update_rate>
          <ray>
            <scan>
              <horizontal>
                <samples>1440</samples>
                <resolution>0.2</resolution>
                <min_angle>-3.14159</min_angle>
                <max_angle>3.14159</max_angle>
              </horizontal>
              <vertical>
                <samples>1</samples>
                <min_angle>0</min_angle>
                <max_angle>0</max_angle>
              </vertical>
            </scan>
            <range>
              <min>0.1</min>
              <max>30</max>
              <resolution>0.01</resolution>
            </range>
            <noise>
              <type>gaussian</type>
              <mean>0</mean>
              <stddev>0.01</stddev>
            </noise>
          </ray>
          <plugin name='gazebo_ros_head_hokuyo_controller' filename='libgazebo_ros_laser.so'>
            <topicName>/scan</topicName>
            <frameName>sensor_laser</frameName>
            <robotNamespace>/</robotNamespace>
          </plugin>
          <pose>0.01 0 0.525 0 -0 0</pose>
        </sensor>
        <self_collide>0</self_collide>
        <enable_wind>0</enable_wind>
        <kinematic>0</kinematic>
      </link>
      <joint name='caster_wheel_joint' type='revolute'>
        <pose relative_to='base_footprint'>0.085 0 0.004 0 -0 0</pose>
        <parent>base_footprint</parent>
        <child>caster_wheel</child>
        <axis>
          <xyz>0 1 0</xyz>
          <limit>
            <lower>-1e+16</lower>
            <upper>1e+16</upper>
          </limit>
          <dynamics>
            <spring_reference>0</spring_reference>
            <spring_stiffness>0</spring_stiffness>
          </dynamics>
        </axis>
      </joint>
      <link name='caster_wheel'>
        <pose relative_to='caster_wheel_joint'>0 0 0 0 -0 0</pose>
        <inertial>
          <pose>0 0 0 0 -0 0</pose>
          <mass>5</mass>
          <inertia>
            <ixx>0.0003125</ixx>
            <ixy>0</ixy>
            <ixz>0</ixz>
            <iyy>0.0003125</iyy>
            <iyz>0</iyz>
            <izz>0.0003125</izz>
          </inertia>
        </inertial>
        <collision name='caster_wheel_collision'>
          <pose>0 0 0 0 -0 0</pose>
          <geometry>
            <sphere>
              <radius>0.0125</radius>
            </sphere>
          </geometry>
          <max_contacts>10</max_contacts>
          <surface>
            <contact>
              <ode/>
            </contact>
            <bounce/>
            <friction>
              <torsional>
                <ode/>
              </torsional>
              <ode/>
            </friction>
          </surface>
        </collision>
        <visual name='caster_wheel_visual'>
          <pose>0 0 0 0 -0 0</pose>
          <geometry>
            <sphere>
              <radius>0.0125</radius>
            </sphere>
          </geometry>
        </visual>
        <self_collide>0</self_collide>
        <enable_wind>0</enable_wind>
        <kinematic>0</kinematic>
      </link>
      <joint name='left_wheel_joint' type='revolute'>
        <pose relative_to='base_footprint'>-0.0725 0.1145 0.0324 0 -0 0</pose>
        <parent>base_footprint</parent>
        <child>left_wheel</child>
        <axis>
          <xyz>0 1 0</xyz>
          <limit>
            <lower>-1e+16</lower>
            <upper>1e+16</upper>
          </limit>
          <dynamics>
            <spring_reference>0</spring_reference>
            <spring_stiffness>0</spring_stiffness>
          </dynamics>
        </axis>
      </joint>
      <link name='left_wheel'>
        <pose relative_to='left_wheel_joint'>0 0 0 0 -0 0</pose>
        <inertial>
          <pose>0 0 0 0 -0 0</pose>
          <mass>10</mass>
          <inertia>
            <ixx>0.0279569</ixx>
            <ixy>0</ixy>
            <ixz>0</ixz>
            <iyy>0.0279569</iyy>
            <iyz>0</iyz>
            <izz>0.0516128</izz>
          </inertia>
        </inertial>
        <collision name='left_wheel_collision'>
          <pose>0 0 0 0 -0 0</pose>
          <geometry>
            <mesh>
              <scale>1 1 1</scale>
              <uri>/home/tuttu/ros_ws/src/pluto/models/Wheel.dae</uri>
            </mesh>
          </geometry>
          <max_contacts>10</max_contacts>
          <surface>
            <contact>
              <ode/>
            </contact>
            <bounce/>
            <friction>
              <torsional>
                <ode/>
              </torsional>
              <ode/>
            </friction>
          </surface>
        </collision>
        <visual name='left_wheel_visual'>
          <pose>0 0 0 0 -0 0</pose>
          <geometry>
            <mesh>
              <scale>1 1 1</scale>
              <uri>/home/tuttu/ros_ws/src/pluto/models/Wheel.dae</uri>
            </mesh>
          </geometry>
        </visual>
        <self_collide>0</self_collide>
        <enable_wind>0</enable_wind>
        <kinematic>0</kinematic>
      </link>
      <joint name='right_wheel_joint' type='revolute'>
        <pose relative_to='base_footprint'>-0.0725 -0.1145 0.0324 0 -0 0</pose>
        <parent>base_footprint</parent>
        <child>right_wheel</child>
        <axis>
          <xyz>0 1 0</xyz>
          <limit>
            <lower>-1e+16</lower>
            <upper>1e+16</upper>
          </limit>
          <dynamics>
            <spring_reference>0</spring_reference>
            <spring_stiffness>0</spring_stiffness>
          </dynamics>
        </axis>
      </joint>
      <link name='right_wheel'>
        <pose relative_to='right_wheel_joint'>0 0 0 0 -0 0</pose>
        <inertial>
          <pose>0 0 0 0 -0 0</pose>
          <mass>10</mass>
          <inertia>
            <ixx>0.0279569</ixx>
            <ixy>0</ixy>
            <ixz>0</ixz>
            <iyy>0.0279569</iyy>
            <iyz>0</iyz>
            <izz>0.0516128</izz>
          </inertia>
        </inertial>
        <collision name='right_wheel_collision'>
          <pose>0 0 0 0 -0 0</pose>
          <geometry>
            <mesh>
              <scale>1 1 1</scale>
              <uri>/home/tuttu/ros_ws/src/pluto/models/Wheel.dae</uri>
            </mesh>
          </geometry>
          <max_contacts>10</max_contacts>
          <surface>
            <contact>
              <ode/>
            </contact>
            <bounce/>
            <friction>
              <torsional>
                <ode/>
              </torsional>
              <ode/>
            </friction>
          </surface>
        </collision>
        <visual name='right_wheel_visual'>
          <pose>0 0 0 0 -0 0</pose>
          <geometry>
            <mesh>
              <scale>1 1 1</scale>
              <uri>/home/tuttu/ros_ws/src/pluto/models/Wheel.dae</uri>
            </mesh>
          </geometry>
        </visual>
        <self_collide>0</self_collide>
        <enable_wind>0</enable_wind>
        <kinematic>0</kinematic>
      </link>
      <joint name='head_joint' type='revolute'>
        <pose relative_to='base_footprint'>0.01 0 0.47 0 -0 0</pose>
        <parent>base_footprint</parent>
        <child>head</child>
        <axis>
          <xyz>0 0 1</xyz>
          <limit>
            <lower>-1.79769e+308</lower>
            <upper>1.79769e+308</upper>
            <effort>1</effort>
            <velocity>1</velocity>
          </limit>
          <dynamics>
            <spring_reference>0</spring_reference>
            <spring_stiffness>0</spring_stiffness>
          </dynamics>
        </axis>
      </joint>
      <link name='head'>
        <pose relative_to='head_joint'>0 0 0 0 -0 0</pose>
        <inertial>
          <pose>0 0 0 0 -0 0</pose>
          <mass>1</mass>
          <inertia>
            <ixx>0.00526881</ixx>
            <ixy>0</ixy>
            <ixz>0</ixz>
            <iyy>0.00526881</iyy>
            <iyz>0</iyz>
            <izz>0.00526881</izz>
          </inertia>
        </inertial>
        <collision name='head_collision'>
          <pose>0 0 0 0 -0 0</pose>
          <geometry>
            <mesh>
              <scale>1 1 1</scale>
              <uri>/home/tuttu/ros_ws/src/pluto/models/Head.dae</uri>
            </mesh>
          </geometry>
          <max_contacts>10</max_contacts>
          <surface>
            <contact>
              <ode/>
            </contact>
            <bounce/>
            <friction>
              <torsional>
                <ode/>
              </torsional>
              <ode/>
            </friction>
          </surface>
        </collision>
        <visual name='head_visual'>
          <pose>0 0 0 0 -0 0</pose>
          <geometry>
            <mesh>
              <scale>1 1 1</scale>
              <uri>/home/tuttu/ros_ws/src/pluto/models/Head.dae</uri>
            </mesh>
          </geometry>
        </visual>
        <self_collide>0</self_collide>
        <enable_wind>0</enable_wind>
        <kinematic>0</kinematic>
      </link>
      <joint name='left_shoulder_joint' type='revolute'>
        <pose relative_to='base_footprint'>0 0.055 0.372 0 -0 0</pose>
        <parent>base_footprint</parent>
        <child>left_shoulder</child>
        <axis>
          <xyz>0 1 0</xyz>
          <limit>
            <lower>-1.79769e+308</lower>
            <upper>1.79769e+308</upper>
            <effort>30</effort>
            <velocity>1</velocity>
          </limit>
          <dynamics>
            <spring_reference>0</spring_reference>
            <spring_stiffness>0</spring_stiffness>
          </dynamics>
        </axis>
      </joint>
      <link name='left_shoulder'>
        <pose relative_to='left_shoulder_joint'>0 0 0 0 -0 0</pose>
        <inertial>
          <pose>0 0 0 0 -0 0</pose>
          <mass>3</mass>
          <inertia>
            <ixx>0.00306451</ixx>
            <ixy>0</ixy>
            <ixz>0</ixz>
            <iyy>0.00306451</iyy>
            <iyz>0</iyz>
            <izz>0.00217741</izz>
          </inertia>
        </inertial>
        <collision name='left_shoulder_collision'>
          <pose>0 0 0 3.14159 -0 0</pose>
          <geometry>
            <mesh>
              <scale>1 1 1</scale>
              <uri>/home/tuttu/ros_ws/src/pluto/models/Shoulder.dae</uri>
            </mesh>
          </geometry>
          <max_contacts>10</max_contacts>
          <surface>
            <contact>
              <ode/>
            </contact>
            <bounce/>
            <friction>
              <torsional>
                <ode/>
              </torsional>
              <ode/>
            </friction>
          </surface>
        </collision>
        <visual name='left_shoulder_visual'>
          <pose>0 0 0 3.14159 -0 0</pose>
          <geometry>
            <mesh>
              <scale>1 1 1</scale>
              <uri>/home/tuttu/ros_ws/src/pluto/models/Shoulder.dae</uri>
            </mesh>
          </geometry>
        </visual>
        <self_collide>0</self_collide>
        <enable_wind>0</enable_wind>
        <kinematic>0</kinematic>
      </link>
      <joint name='left_upper_arm_bottom_joint' type='revolute'>
        <pose relative_to='left_shoulder'>0 0.0225 0 0 -0 0</pose>
        <parent>left_shoulder</parent>
        <child>left_upper_arm_bottom</child>
        <axis>
          <xyz>1 0 0</xyz>
          <limit>
            <lower>-1.79769e+308</lower>
            <upper>1.79769e+308</upper>
            <effort>30</effort>
            <velocity>1</velocity>
          </limit>
          <dynamics>
            <spring_reference>0</spring_reference>
            <spring_stiffness>0</spring_stiffness>
          </dynamics>
        </axis>
      </joint>
      <link name='left_upper_arm_bottom'>
        <pose relative_to='left_upper_arm_bottom_joint'>0 0 0 0 -0 0</pose>
        <inertial>
          <pose>0 0 0 0 -0 0</pose>
          <mass>0.5</mass>
          <inertia>
            <ixx>0.00281417</ixx>
            <ixy>0</ixy>
            <ixz>0</ixz>
            <iyy>0.00281417</iyy>
            <iyz>0</iyz>
            <izz>0.000252016</izz>
          </inertia>
        </inertial>
        <collision name='left_upper_arm_bottom_collision'>
          <pose>0 0 0 3.14159 -0 0</pose>
          <geometry>
            <mesh>
              <scale>1 1 1</scale>
              <uri>/home/tuttu/ros_ws/src/pluto/models/UpperArmBottom.dae</uri>
            </mesh>
          </geometry>
          <max_contacts>10</max_contacts>
          <surface>
            <contact>
              <ode/>
            </contact>
            <bounce/>
            <friction>
              <torsional>
                <ode/>
              </torsional>
              <ode/>
            </friction>
          </surface>
        </collision>
        <visual name='left_upper_arm_bottom_visual'>
          <pose>0 0 0 0 -0 3.14159</pose>
          <geometry>
            <mesh>
              <scale>1 1 1</scale>
              <uri>/home/tuttu/ros_ws/src/pluto/models/UpperArmBottom.dae</uri>
            </mesh>
          </geometry>
        </visual>
        <self_collide>0</self_collide>
        <enable_wind>0</enable_wind>
        <kinematic>0</kinematic>
      </link>
      <joint name='left_upper_arm_top_joint' type='revolute'>
        <pose relative_to='left_upper_arm_bottom'>0 0 -0.03125 0 -0 0</pose>
        <parent>left_upper_arm_bottom</parent>
        <child>left_upper_arm_top</child>
        <axis>
          <xyz>0 0 1</xyz>
          <limit>
            <lower>-1.79769e+308</lower>
            <upper>1.79769e+308</upper>
            <effort>1</effort>
            <velocity>1</velocity>
          </limit>
          <dynamics>
            <spring_reference>0</spring_reference>
            <spring_stiffness>0</spring_stiffness>
          </dynamics>
        </axis>
      </joint>
      <link name='left_upper_arm_top'>
        <pose relative_to='left_upper_arm_top_joint'>0 0 0 0 -0 0</pose>
        <inertial>
          <pose>0 0 0 0 -0 0</pose>
          <mass>4</mass>
          <inertia>
            <ixx>0.0225134</ixx>
            <ixy>0</ixy>
            <ixz>0</ixz>
            <iyy>0.0225134</iyy>
            <iyz>0</iyz>
            <izz>0.00201613</izz>
          </inertia>
        </inertial>
        <collision name='left_upper_arm_top_collision'>
          <pose>0 0 0 3.14159 -0 0</pose>
          <geometry>
            <mesh>
              <scale>1 1 1</scale>
              <uri>/home/tuttu/ros_ws/src/pluto/models/UpperArmTop.dae</uri>
            </mesh>
          </geometry>
          <max_contacts>10</max_contacts>
          <surface>
            <contact>
              <ode/>
            </contact>
            <bounce/>
            <friction>
              <torsional>
                <ode/>
              </torsional>
              <ode/>
            </friction>
          </surface>
        </collision>
        <visual name='left_upper_arm_top_visual'>
          <pose>0 0 0 0 -0 3.14159</pose>
          <geometry>
            <mesh>
              <scale>1 1 1</scale>
              <uri>/home/tuttu/ros_ws/src/pluto/models/UpperArmTop.dae</uri>
            </mesh>
          </geometry>
        </visual>
        <self_collide>0</self_collide>
        <enable_wind>0</enable_wind>
        <kinematic>0</kinematic>
      </link>
      <joint name='left_forearm_bottom_joint' type='revolute'>
        <pose relative_to='left_upper_arm_top'>0 0 -0.07625 3.14159 1.57079 3.14159</pose>
        <parent>left_upper_arm_top</parent>
        <child>left_forearm_bottom</child>
        <axis>
          <xyz>0 1 0</xyz>
          <limit>
            <lower>-1.79769e+308</lower>
            <upper>1.79769e+308</upper>
            <effort>10</effort>
            <velocity>1</velocity>
          </limit>
          <dynamics>
            <spring_reference>0</spring_reference>
            <spring_stiffness>0</spring_stiffness>
          </dynamics>
        </axis>
      </joint>
      <link name='left_forearm_bottom'>
        <pose relative_to='left_forearm_bottom_joint'>0 0 0 0 -0 0</pose>
        <inertial>
          <pose>0 0 0 0 -0 0</pose>
          <mass>0.5</mass>
          <inertia>
            <ixx>0.000556114</ixx>
            <ixy>0</ixy>
            <ixz>0</ixz>
            <iyy>0.000556114</iyy>
            <iyz>0</iyz>
            <izz>0.000252016</izz>
          </inertia>
        </inertial>
        <collision name='left_forearm_bottom_collision'>
          <pose>0 0 0 3.14159 -0 0</pose>
          <geometry>
            <mesh>
              <scale>1 1 1</scale>
              <uri>/home/tuttu/ros_ws/src/pluto/models/ForearmBottom.dae</uri>
            </mesh>
          </geometry>
          <max_contacts>10</max_contacts>
          <surface>
            <contact>
              <ode/>
            </contact>
            <bounce/>
            <friction>
              <torsional>
                <ode/>
              </torsional>
              <ode/>
            </friction>
          </surface>
        </collision>
        <visual name='left_forearm_bottom_visual'>
          <pose>0 0 0 3.14159 -0 0</pose>
          <geometry>
            <mesh>
              <scale>1 1 1</scale>
              <uri>/home/tuttu/ros_ws/src/pluto/models/ForearmBottom.dae</uri>
            </mesh>
          </geometry>
        </visual>
        <self_collide>0</self_collide>
        <enable_wind>0</enable_wind>
        <kinematic>0</kinematic>
      </link>
      <joint name='left_forearm_top_joint' type='revolute'>
        <pose relative_to='left_forearm_bottom'>0.029 0 0 0 -0 0</pose>
        <parent>left_forearm_bottom</parent>
        <child>left_forearm_top</child>
        <axis>
          <xyz>1 0 0</xyz>
          <limit>
            <lower>-1.79769e+308</lower>
            <upper>1.79769e+308</upper>
            <effort>1</effort>
            <velocity>1</velocity>
          </limit>
          <dynamics>
            <spring_reference>0</spring_reference>
            <spring_stiffness>0</spring_stiffness>
          </dynamics>
        </axis>
      </joint>
      <link name='left_forearm_top'>
        <pose relative_to='left_forearm_top_joint'>0 0 0 0 -0 0</pose>
        <inertial>
          <pose>0 0 0 0 -0 0</pose>
          <mass>0.4</mass>
          <inertia>
            <ixx>0.000444892</ixx>
            <ixy>0</ixy>
            <ixz>0</ixz>
            <iyy>0.000444892</iyy>
            <iyz>0</iyz>
            <izz>0.000201613</izz>
          </inertia>
        </inertial>
        <collision name='left_forearm_top_collision'>
          <pose>0 0 0 3.14159 -0 0</pose>
          <geometry>
            <mesh>
              <scale>1 1 1</scale>
              <uri>/home/tuttu/ros_ws/src/pluto/models/ForearmTop.dae</uri>
            </mesh>
          </geometry>
          <max_contacts>10</max_contacts>
          <surface>
            <contact>
              <ode/>
            </contact>
            <bounce/>
            <friction>
              <torsional>
                <ode/>
              </torsional>
              <ode/>
            </friction>
          </surface>
        </collision>
        <visual name='left_forearm_top_visual'>
          <pose>0 0 0 3.14159 -0 0</pose>
          <geometry>
            <mesh>
              <scale>1 1 1</scale>
              <uri>/home/tuttu/ros_ws/src/pluto/models/ForearmTop.dae</uri>
            </mesh>
          </geometry>
        </visual>
        <self_collide>0</self_collide>
        <enable_wind>0</enable_wind>
        <kinematic>0</kinematic>
      </link>
      <joint name='left_palm_joint' type='revolute'>
        <pose relative_to='left_forearm_top'>0.06525 0 0 0 -0 0</pose>
        <parent>left_forearm_top</parent>
        <child>left_palm</child>
        <axis>
          <xyz>0 0 1</xyz>
          <limit>
            <lower>-1.79769e+308</lower>
            <upper>1.79769e+308</upper>
            <effort>1</effort>
            <velocity>1</velocity>
          </limit>
          <dynamics>
            <spring_reference>0</spring_reference>
            <spring_stiffness>0</spring_stiffness>
          </dynamics>
        </axis>
      </joint>
      <link name='left_palm'>
        <pose relative_to='left_palm_joint'>0 0 0 0 -0 0</pose>
        <inertial>
          <pose>0.00025 -0.000172 0 0 -0 0</pose>
          <mass>0.32</mass>
          <inertia>
            <ixx>0.000447453</ixx>
            <ixy>2.0625e-07</ixy>
            <ixz>0</ixz>
            <iyy>0.000860513</iyy>
            <iyz>0</iyz>
            <izz>0.000447753</izz>
          </inertia>
        </inertial>
        <collision name='left_palm_collision'>
          <pose>0 0 0 0 -0 0</pose>
          <geometry>
            <mesh>
              <scale>1 1 1</scale>
              <uri>/home/tuttu/ros_ws/src/pluto/models/LeftPalm.dae</uri>
            </mesh>
          </geometry>
          <max_contacts>10</max_contacts>
          <surface>
            <contact>
              <ode/>
            </contact>
            <bounce/>
            <friction>
              <torsional>
                <ode/>
              </torsional>
              <ode/>
            </friction>
          </surface>
        </collision>
        <collision name='left_palm_surface_collision_1'>
          <pose>0.004 -0.00275 0 0 -0 0</pose>
          <geometry>
            <mesh>
              <scale>1 1 1</scale>
              <uri>/home/tuttu/ros_ws/src/pluto/models/LeftPalmSurface.dae</uri>
            </mesh>
          </geometry>
          <max_contacts>10</max_contacts>
          <surface>
            <contact>
              <ode/>
            </contact>
            <bounce/>
            <friction>
              <torsional>
                <ode/>
              </torsional>
              <ode/>
            </friction>
          </surface>
        </collision>
        <visual name='left_palm_visual'>
          <pose>0 0 0 0 -0 0</pose>
          <geometry>
            <mesh>
              <scale>1 1 1</scale>
              <uri>/home/tuttu/ros_ws/src/pluto/models/LeftPalm.dae</uri>
            </mesh>
          </geometry>
        </visual>
        <visual name='left_palm_surface_visual_1'>
          <pose>0.004 -0.00275 0 0 -0 0</pose>
          <geometry>
            <mesh>
              <scale>1 1 1</scale>
              <uri>/home/tuttu/ros_ws/src/pluto/models/LeftPalmSurface.dae</uri>
            </mesh>
          </geometry>
        </visual>
        <self_collide>0</self_collide>
        <enable_wind>0</enable_wind>
        <kinematic>0</kinematic>
      </link>
      <joint name='left_index_bottom_joint' type='revolute'>
        <pose relative_to='left_palm'>0.0395 0.0025 0.0132 0 -0 0</pose>
        <parent>left_palm</parent>
        <child>left_index_bottom</child>
        <axis>
          <xyz>0 0 1</xyz>
          <limit>
            <lower>-1.79769e+308</lower>
            <upper>1.79769e+308</upper>
            <effort>1</effort>
            <velocity>1</velocity>
          </limit>
          <dynamics>
            <spring_reference>0</spring_reference>
            <spring_stiffness>0</spring_stiffness>
          </dynamics>
        </axis>
      </joint>
      <link name='left_index_bottom'>
        <pose relative_to='left_index_bottom_joint'>0 0 0 0 -0 0</pose>
        <inertial>
          <pose>0 0 0 0 -0 0</pose>
          <mass>0.02</mass>
          <inertia>
            <ixx>4.50268e-06</ixx>
            <ixy>0</ixy>
            <ixz>0</ixz>
            <iyy>4.50268e-06</iyy>
            <iyz>0</iyz>
            <izz>4.03225e-07</izz>
          </inertia>
        </inertial>
        <collision name='left_index_bottom_collision'>
          <pose>0 0 0 3.14159 -0 0</pose>
          <geometry>
            <mesh>
              <scale>1 1 1</scale>
              <uri>/home/tuttu/ros_ws/src/pluto/models/IndexBottom.dae</uri>
            </mesh>
          </geometry>
          <max_contacts>10</max_contacts>
          <surface>
            <contact>
              <ode/>
            </contact>
            <bounce/>
            <friction>
              <torsional>
                <ode/>
              </torsional>
              <ode/>
            </friction>
          </surface>
        </collision>
        <visual name='left_index_bottom_visual'>
          <pose>0 0 0 3.14159 -0 0</pose>
          <geometry>
            <mesh>
              <scale>1 1 1</scale>
              <uri>/home/tuttu/ros_ws/src/pluto/models/IndexBottom.dae</uri>
            </mesh>
          </geometry>
        </visual>
        <self_collide>0</self_collide>
        <enable_wind>0</enable_wind>
        <kinematic>0</kinematic>
      </link>
      <joint name='left_index_top_joint' type='revolute'>
        <pose relative_to='left_index_bottom'>0.019 0.001 0 0 -0 0</pose>
        <parent>left_index_bottom</parent>
        <child>left_index_top</child>
        <axis>
          <xyz>0 0 1</xyz>
          <limit>
            <lower>-1.79769e+308</lower>
            <upper>1.79769e+308</upper>
            <effort>1</effort>
            <velocity>1</velocity>
          </limit>
          <dynamics>
            <spring_reference>0</spring_reference>
            <spring_stiffness>0</spring_stiffness>
          </dynamics>
        </axis>
      </joint>
      <link name='left_index_top'>
        <pose relative_to='left_index_top_joint'>0 0 0 0 -0 0</pose>
        <inertial>
          <pose>0 0 0 0 -0 0</pose>
          <mass>0.02</mass>
          <inertia>
            <ixx>4.50268e-06</ixx>
            <ixy>0</ixy>
            <ixz>0</ixz>
            <iyy>4.50268e-06</iyy>
            <iyz>0</iyz>
            <izz>4.03225e-07</izz>
          </inertia>
        </inertial>
        <collision name='left_index_top_collision'>
          <pose>0 0 0 3.14159 -0 0</pose>
          <geometry>
            <mesh>
              <scale>1 1 1</scale>
              <uri>/home/tuttu/ros_ws/src/pluto/models/IndexTop.dae</uri>
            </mesh>
          </geometry>
          <max_contacts>10</max_contacts>
          <surface>
            <contact>
              <ode/>
            </contact>
            <bounce/>
            <friction>
              <torsional>
                <ode/>
              </torsional>
              <ode/>
            </friction>
          </surface>
        </collision>
        <visual name='left_index_top_visual'>
          <pose>0 0 0 3.14159 -0 0</pose>
          <geometry>
            <mesh>
              <scale>1 1 1</scale>
              <uri>/home/tuttu/ros_ws/src/pluto/models/IndexTop.dae</uri>
            </mesh>
          </geometry>
        </visual>
        <self_collide>0</self_collide>
        <enable_wind>0</enable_wind>
        <kinematic>0</kinematic>
      </link>
      <joint name='left_middle_bottom_joint' type='revolute'>
        <pose relative_to='left_palm'>0.0395 0.00325 0.00425 0 -0 0</pose>
        <parent>left_palm</parent>
        <child>left_middle_bottom</child>
        <axis>
          <xyz>0 0 1</xyz>
          <limit>
            <lower>-1.79769e+308</lower>
            <upper>1.79769e+308</upper>
            <effort>1</effort>
            <velocity>1</velocity>
          </limit>
          <dynamics>
            <spring_reference>0</spring_reference>
            <spring_stiffness>0</spring_stiffness>
          </dynamics>
        </axis>
      </joint>
      <link name='left_middle_bottom'>
        <pose relative_to='left_middle_bottom_joint'>0 0 0 0 -0 0</pose>
        <inertial>
          <pose>0 0 0 0 -0 0</pose>
          <mass>0.02</mass>
          <inertia>
            <ixx>4.50268e-06</ixx>
            <ixy>0</ixy>
            <ixz>0</ixz>
            <iyy>4.50268e-06</iyy>
            <iyz>0</iyz>
            <izz>4.03225e-07</izz>
          </inertia>
        </inertial>
        <collision name='left_middle_bottom_collision'>
          <pose>0 0 0 3.14159 -0 0</pose>
          <geometry>
            <mesh>
              <scale>1 1 1</scale>
              <uri>/home/tuttu/ros_ws/src/pluto/models/MiddleBottom.dae</uri>
            </mesh>
          </geometry>
          <max_contacts>10</max_contacts>
          <surface>
            <contact>
              <ode/>
            </contact>
            <bounce/>
            <friction>
              <torsional>
                <ode/>
              </torsional>
              <ode/>
            </friction>
          </surface>
        </collision>
        <visual name='left_middle_bottom_visual'>
          <pose>0 0 0 3.14159 -0 0</pose>
          <geometry>
            <mesh>
              <scale>1 1 1</scale>
              <uri>/home/tuttu/ros_ws/src/pluto/models/MiddleBottom.dae</uri>
            </mesh>
          </geometry>
        </visual>
        <self_collide>0</self_collide>
        <enable_wind>0</enable_wind>
        <kinematic>0</kinematic>
      </link>
      <joint name='left_middle_top_joint' type='revolute'>
        <pose relative_to='left_middle_bottom'>0.0205 0 -0.0002 0 -0 0</pose>
        <parent>left_middle_bottom</parent>
        <child>left_middle_top</child>
        <axis>
          <xyz>0 0 1</xyz>
          <limit>
            <lower>-1.79769e+308</lower>
            <upper>1.79769e+308</upper>
            <effort>1</effort>
            <velocity>1</velocity>
          </limit>
          <dynamics>
            <spring_reference>0</spring_reference>
            <spring_stiffness>0</spring_stiffness>
          </dynamics>
        </axis>
      </joint>
      <link name='left_middle_top'>
        <pose relative_to='left_middle_top_joint'>0 0 0 0 -0 0</pose>
        <inertial>
          <pose>0 0 0 0 -0 0</pose>
          <mass>0.02</mass>
          <inertia>
            <ixx>4.50268e-06</ixx>
            <ixy>0</ixy>
            <ixz>0</ixz>
            <iyy>4.50268e-06</iyy>
            <iyz>0</iyz>
            <izz>4.03225e-07</izz>
          </inertia>
        </inertial>
        <collision name='left_middle_top_collision'>
          <pose>0 0 0 3.14159 -0 0</pose>
          <geometry>
            <mesh>
              <scale>1 1 1</scale>
              <uri>/home/tuttu/ros_ws/src/pluto/models/MiddleTop.dae</uri>
            </mesh>
          </geometry>
          <max_contacts>10</max_contacts>
          <surface>
            <contact>
              <ode/>
            </contact>
            <bounce/>
            <friction>
              <torsional>
                <ode/>
              </torsional>
              <ode/>
            </friction>
          </surface>
        </collision>
        <visual name='left_middle_top_visual'>
          <pose>0 0 0 3.14159 -0 0</pose>
          <geometry>
            <mesh>
              <scale>1 1 1</scale>
              <uri>/home/tuttu/ros_ws/src/pluto/models/MiddleTop.dae</uri>
            </mesh>
          </geometry>
        </visual>
        <self_collide>0</self_collide>
        <enable_wind>0</enable_wind>
        <kinematic>0</kinematic>
      </link>
      <joint name='left_pinky_bottom_joint' type='revolute'>
        <pose relative_to='left_palm'>0.0395 0.00325 -0.0125 0 -0 0</pose>
        <parent>left_palm</parent>
        <child>left_pinky_bottom</child>
        <axis>
          <xyz>0 0 1</xyz>
          <limit>
            <lower>-1.79769e+308</lower>
            <upper>1.79769e+308</upper>
            <effort>1</effort>
            <velocity>1</velocity>
          </limit>
          <dynamics>
            <spring_reference>0</spring_reference>
            <spring_stiffness>0</spring_stiffness>
          </dynamics>
        </axis>
      </joint>
      <link name='left_pinky_bottom'>
        <pose relative_to='left_pinky_bottom_joint'>0 0 0 0 -0 0</pose>
        <inertial>
          <pose>0 0 0 0 -0 0</pose>
          <mass>0.02</mass>
          <inertia>
            <ixx>4.50268e-06</ixx>
            <ixy>0</ixy>
            <ixz>0</ixz>
            <iyy>4.50268e-06</iyy>
            <iyz>0</iyz>
            <izz>4.03225e-07</izz>
          </inertia>
        </inertial>
        <collision name='left_pinky_bottom_collision'>
          <pose>0 0 0 3.14159 -0 0</pose>
          <geometry>
            <mesh>
              <scale>1 1 1</scale>
              <uri>/home/tuttu/ros_ws/src/pluto/models/PinkyBottom.dae</uri>
            </mesh>
          </geometry>
          <max_contacts>10</max_contacts>
          <surface>
            <contact>
              <ode/>
            </contact>
            <bounce/>
            <friction>
              <torsional>
                <ode/>
              </torsional>
              <ode/>
            </friction>
          </surface>
        </collision>
        <visual name='left_pinky_bottom_visual'>
          <pose>0 0 0 3.14159 -0 0</pose>
          <geometry>
            <mesh>
              <scale>1 1 1</scale>
              <uri>/home/tuttu/ros_ws/src/pluto/models/PinkyBottom.dae</uri>
            </mesh>
          </geometry>
        </visual>
        <self_collide>0</self_collide>
        <enable_wind>0</enable_wind>
        <kinematic>0</kinematic>
      </link>
      <joint name='left_pinky_top_joint' type='revolute'>
        <pose relative_to='left_pinky_bottom'>0.0145 -0.00025 0.0002 0 -0 0</pose>
        <parent>left_pinky_bottom</parent>
        <child>left_pinky_top</child>
        <axis>
          <xyz>0 0 1</xyz>
          <limit>
            <lower>-1.79769e+308</lower>
            <upper>1.79769e+308</upper>
            <effort>1</effort>
            <velocity>1</velocity>
          </limit>
          <dynamics>
            <spring_reference>0</spring_reference>
            <spring_stiffness>0</spring_stiffness>
          </dynamics>
        </axis>
      </joint>
      <link name='left_pinky_top'>
        <pose relative_to='left_pinky_top_joint'>0 0 0 0 -0 0</pose>
        <inertial>
          <pose>0 0 0 0 -0 0</pose>
          <mass>0.02</mass>
          <inertia>
            <ixx>4.50268e-06</ixx>
            <ixy>0</ixy>
            <ixz>0</ixz>
            <iyy>4.50268e-06</iyy>
            <iyz>0</iyz>
            <izz>4.03225e-07</izz>
          </inertia>
        </inertial>
        <collision name='left_pinky_top_collision'>
          <pose>0 0 0 3.14159 -0 0</pose>
          <geometry>
            <mesh>
              <scale>1 1 1</scale>
              <uri>/home/tuttu/ros_ws/src/pluto/models/PinkyTop.dae</uri>
            </mesh>
          </geometry>
          <max_contacts>10</max_contacts>
          <surface>
            <contact>
              <ode/>
            </contact>
            <bounce/>
            <friction>
              <torsional>
                <ode/>
              </torsional>
              <ode/>
            </friction>
          </surface>
        </collision>
        <visual name='left_pinky_top_visual'>
          <pose>0 0 0 3.14159 -0 0</pose>
          <geometry>
            <mesh>
              <scale>1 1 1</scale>
              <uri>/home/tuttu/ros_ws/src/pluto/models/PinkyTop.dae</uri>
            </mesh>
          </geometry>
        </visual>
        <self_collide>0</self_collide>
        <enable_wind>0</enable_wind>
        <kinematic>0</kinematic>
      </link>
      <joint name='left_ring_bottom_joint' type='revolute'>
        <pose relative_to='left_palm'>0.0395 0.00325 -0.00425 0 -0 0</pose>
        <parent>left_palm</parent>
        <child>left_ring_bottom</child>
        <axis>
          <xyz>0 0 1</xyz>
          <limit>
            <lower>-1.79769e+308</lower>
            <upper>1.79769e+308</upper>
            <effort>1</effort>
            <velocity>1</velocity>
          </limit>
          <dynamics>
            <spring_reference>0</spring_reference>
            <spring_stiffness>0</spring_stiffness>
          </dynamics>
        </axis>
      </joint>
      <link name='left_ring_bottom'>
        <pose relative_to='left_ring_bottom_joint'>0 0 0 0 -0 0</pose>
        <inertial>
          <pose>0 0 0 0 -0 0</pose>
          <mass>0.02</mass>
          <inertia>
            <ixx>4.50268e-06</ixx>
            <ixy>0</ixy>
            <ixz>0</ixz>
            <iyy>4.50268e-06</iyy>
            <iyz>0</iyz>
            <izz>4.03225e-07</izz>
          </inertia>
        </inertial>
        <collision name='left_ring_bottom_collision'>
          <pose>0 0 0 3.14159 -0 0</pose>
          <geometry>
            <mesh>
              <scale>1 1 1</scale>
              <uri>/home/tuttu/ros_ws/src/pluto/models/RingBottom.dae</uri>
            </mesh>
          </geometry>
          <max_contacts>10</max_contacts>
          <surface>
            <contact>
              <ode/>
            </contact>
            <bounce/>
            <friction>
              <torsional>
                <ode/>
              </torsional>
              <ode/>
            </friction>
          </surface>
        </collision>
        <visual name='left_ring_bottom_visual'>
          <pose>0 0 0 3.14159 -0 0</pose>
          <geometry>
            <mesh>
              <scale>1 1 1</scale>
              <uri>/home/tuttu/ros_ws/src/pluto/models/RingBottom.dae</uri>
            </mesh>
          </geometry>
        </visual>
        <self_collide>0</self_collide>
        <enable_wind>0</enable_wind>
        <kinematic>0</kinematic>
      </link>
      <joint name='left_ring_top_joint' type='revolute'>
        <pose relative_to='left_ring_bottom'>0.019 -0.0005 0.0002 0 -0 0</pose>
        <parent>left_ring_bottom</parent>
        <child>left_ring_top</child>
        <axis>
          <xyz>0 0 1</xyz>
          <limit>
            <lower>-1.79769e+308</lower>
            <upper>1.79769e+308</upper>
            <effort>1</effort>
            <velocity>1</velocity>
          </limit>
          <dynamics>
            <spring_reference>0</spring_reference>
            <spring_stiffness>0</spring_stiffness>
          </dynamics>
        </axis>
      </joint>
      <link name='left_ring_top'>
        <pose relative_to='left_ring_top_joint'>0 0 0 0 -0 0</pose>
        <inertial>
          <pose>0 0 0 0 -0 0</pose>
          <mass>0.02</mass>
          <inertia>
            <ixx>4.50268e-06</ixx>
            <ixy>0</ixy>
            <ixz>0</ixz>
            <iyy>4.50268e-06</iyy>
            <iyz>0</iyz>
            <izz>4.03225e-07</izz>
          </inertia>
        </inertial>
        <collision name='left_ring_top_collision'>
          <pose>0 0 0 3.14159 -0 0</pose>
          <geometry>
            <mesh>
              <scale>1 1 1</scale>
              <uri>/home/tuttu/ros_ws/src/pluto/models/RingTop.dae</uri>
            </mesh>
          </geometry>
          <max_contacts>10</max_contacts>
          <surface>
            <contact>
              <ode/>
            </contact>
            <bounce/>
            <friction>
              <torsional>
                <ode/>
              </torsional>
              <ode/>
            </friction>
          </surface>
        </collision>
        <visual name='left_ring_top_visual'>
          <pose>0 0 0 3.14159 -0 0</pose>
          <geometry>
            <mesh>
              <scale>1 1 1</scale>
              <uri>/home/tuttu/ros_ws/src/pluto/models/RingTop.dae</uri>
            </mesh>
          </geometry>
        </visual>
        <self_collide>0</self_collide>
        <enable_wind>0</enable_wind>
        <kinematic>0</kinematic>
      </link>
      <joint name='left_thumb_piece_joint' type='revolute'>
        <pose relative_to='left_palm'>0.014 0.002 0.0125 0 -0 0</pose>
        <parent>left_palm</parent>
        <child>left_thumb_piece</child>
        <axis>
          <xyz>1 0 0</xyz>
          <limit>
            <lower>-1.79769e+308</lower>
            <upper>1.79769e+308</upper>
            <effort>1</effort>
            <velocity>1</velocity>
          </limit>
          <dynamics>
            <spring_reference>0</spring_reference>
            <spring_stiffness>0</spring_stiffness>
          </dynamics>
        </axis>
      </joint>
      <link name='left_thumb_piece'>
        <pose relative_to='left_thumb_piece_joint'>0 0 0 0 -0 0</pose>
        <inertial>
          <pose>0 0 0 0 -0 0</pose>
          <mass>0.1</mass>
          <inertia>
            <ixx>2.68817e-05</ixx>
            <ixy>0</ixy>
            <ixz>0</ixz>
            <iyy>4.30107e-05</iyy>
            <iyz>0</iyz>
            <izz>2.68817e-05</izz>
          </inertia>
        </inertial>
        <collision name='left_thumb_piece_collision'>
          <pose>0 0 0 0 -0 0</pose>
          <geometry>
            <mesh>
              <scale>1 1 1</scale>
              <uri>/home/tuttu/ros_ws/src/pluto/models/LeftThumbPiece.dae</uri>
            </mesh>
          </geometry>
          <max_contacts>10</max_contacts>
          <surface>
            <contact>
              <ode/>
            </contact>
            <bounce/>
            <friction>
              <torsional>
                <ode/>
              </torsional>
              <ode/>
            </friction>
          </surface>
        </collision>
        <visual name='left_thumb_piece_visual'>
          <pose>0 0 0 0 -0 0</pose>
          <geometry>
            <mesh>
              <scale>1 1 1</scale>
              <uri>/home/tuttu/ros_ws/src/pluto/models/LeftThumbPiece.dae</uri>
            </mesh>
          </geometry>
        </visual>
        <self_collide>0</self_collide>
        <enable_wind>0</enable_wind>
        <kinematic>0</kinematic>
      </link>
      <joint name='left_thumb_bottom_joint' type='revolute'>
        <pose relative_to='left_thumb_piece'>0.0035 0.00025 0.011 0 -0 0</pose>
        <parent>left_thumb_piece</parent>
        <child>left_thumb_bottom</child>
        <axis>
          <xyz>0 1 0</xyz>
          <limit>
            <lower>-1.79769e+308</lower>
            <upper>1.79769e+308</upper>
            <effort>1</effort>
            <velocity>1</velocity>
          </limit>
          <dynamics>
            <spring_reference>0</spring_reference>
            <spring_stiffness>0</spring_stiffness>
          </dynamics>
        </axis>
      </joint>
      <link name='left_thumb_bottom'>
        <pose relative_to='left_thumb_bottom_joint'>0 0 0 0 -0 0</pose>
        <inertial>
          <pose>0 0 0 0 -0 0</pose>
          <mass>0.02</mass>
          <inertia>
            <ixx>4.50268e-06</ixx>
            <ixy>0</ixy>
            <ixz>0</ixz>
            <iyy>4.50268e-06</iyy>
            <iyz>0</iyz>
            <izz>4.03225e-07</izz>
          </inertia>
        </inertial>
        <collision name='left_thumb_bottom_collision'>
          <pose>0 0 0 -0.314159 -0 -0.523599</pose>
          <geometry>
            <mesh>
              <scale>1 1 1</scale>
              <uri>/home/tuttu/ros_ws/src/pluto/models/ThumbBottom.dae</uri>
            </mesh>
          </geometry>
          <max_contacts>10</max_contacts>
          <surface>
            <contact>
              <ode/>
            </contact>
            <bounce/>
            <friction>
              <torsional>
                <ode/>
              </torsional>
              <ode/>
            </friction>
          </surface>
        </collision>
        <visual name='left_thumb_bottom_visual'>
          <pose>0 0 0 -0.314159 -0 -0.523599</pose>
          <geometry>
            <mesh>
              <scale>1 1 1</scale>
              <uri>/home/tuttu/ros_ws/src/pluto/models/ThumbBottom.dae</uri>
            </mesh>
          </geometry>
        </visual>
        <self_collide>0</self_collide>
        <enable_wind>0</enable_wind>
        <kinematic>0</kinematic>
      </link>
      <joint name='left_thumb_top_joint' type='revolute'>
        <pose relative_to='left_thumb_bottom'>0.0125 -0.0075 0 0 -0 0</pose>
        <parent>left_thumb_bottom</parent>
        <child>left_thumb_top</child>
        <axis>
          <xyz>0 1 0</xyz>
          <limit>
            <lower>-1.79769e+308</lower>
            <upper>1.79769e+308</upper>
            <effort>1</effort>
            <velocity>1</velocity>
          </limit>
          <dynamics>
            <spring_reference>0</spring_reference>
            <spring_stiffness>0</spring_stiffness>
          </dynamics>
        </axis>
      </joint>
      <link name='left_thumb_top'>
        <pose relative_to='left_thumb_top_joint'>0 0 0 0 -0 0</pose>
        <inertial>
          <pose>0 0 0 0 -0 0</pose>
          <mass>0.02</mass>
          <inertia>
            <ixx>4.50268e-06</ixx>
            <ixy>0</ixy>
            <ixz>0</ixz>
            <iyy>4.50268e-06</iyy>
            <iyz>0</iyz>
            <izz>4.03225e-07</izz>
          </inertia>
        </inertial>
        <collision name='left_thumb_top_collision'>
          <pose>0 0 0 -0.314159 -0 -0.523599</pose>
          <geometry>
            <mesh>
              <scale>1 1 1</scale>
              <uri>/home/tuttu/ros_ws/src/pluto/models/ThumbTop.dae</uri>
            </mesh>
          </geometry>
          <max_contacts>10</max_contacts>
          <surface>
            <contact>
              <ode/>
            </contact>
            <bounce/>
            <friction>
              <torsional>
                <ode/>
              </torsional>
              <ode/>
            </friction>
          </surface>
        </collision>
        <visual name='left_thumb_top_visual'>
          <pose>0 0 0 -0.314159 -0 -0.523599</pose>
          <geometry>
            <mesh>
              <scale>1 1 1</scale>
              <uri>/home/tuttu/ros_ws/src/pluto/models/ThumbTop.dae</uri>
            </mesh>
          </geometry>
        </visual>
        <self_collide>0</self_collide>
        <enable_wind>0</enable_wind>
        <kinematic>0</kinematic>
      </link>
      <joint name='right_shoulder_joint' type='revolute'>
        <pose relative_to='base_footprint'>0 -0.055 0.372 0 -0 0</pose>
        <parent>base_footprint</parent>
        <child>right_shoulder</child>
        <axis>
          <xyz>0 1 0</xyz>
          <limit>
            <lower>-1.79769e+308</lower>
            <upper>1.79769e+308</upper>
            <effort>30</effort>
            <velocity>1</velocity>
          </limit>
          <dynamics>
            <spring_reference>0</spring_reference>
            <spring_stiffness>0</spring_stiffness>
          </dynamics>
        </axis>
      </joint>
      <link name='right_shoulder'>
        <pose relative_to='right_shoulder_joint'>0 0 0 0 -0 0</pose>
        <inertial>
          <pose>0 0 0 0 -0 0</pose>
          <mass>3</mass>
          <inertia>
            <ixx>0.00306451</ixx>
            <ixy>0</ixy>
            <ixz>0</ixz>
            <iyy>0.00306451</iyy>
            <iyz>0</iyz>
            <izz>0.00217741</izz>
          </inertia>
        </inertial>
        <collision name='right_shoulder_collision'>
          <pose>0 0 0 0 -0 0</pose>
          <geometry>
            <mesh>
              <scale>1 1 1</scale>
              <uri>/home/tuttu/ros_ws/src/pluto/models/Shoulder.dae</uri>
            </mesh>
          </geometry>
          <max_contacts>10</max_contacts>
          <surface>
            <contact>
              <ode/>
            </contact>
            <bounce/>
            <friction>
              <torsional>
                <ode/>
              </torsional>
              <ode/>
            </friction>
          </surface>
        </collision>
        <visual name='right_shoulder_visual'>
          <pose>0 0 0 0 -0 0</pose>
          <geometry>
            <mesh>
              <scale>1 1 1</scale>
              <uri>/home/tuttu/ros_ws/src/pluto/models/Shoulder.dae</uri>
            </mesh>
          </geometry>
        </visual>
        <self_collide>0</self_collide>
        <enable_wind>0</enable_wind>
        <kinematic>0</kinematic>
      </link>
      <joint name='right_upper_arm_bottom_joint' type='revolute'>
        <pose relative_to='right_shoulder'>0 -0.0225 0 0 -0 0</pose>
        <parent>right_shoulder</parent>
        <child>right_upper_arm_bottom</child>
        <axis>
          <xyz>1 0 0</xyz>
          <limit>
            <lower>-1.79769e+308</lower>
            <upper>1.79769e+308</upper>
            <effort>30</effort>
            <velocity>1</velocity>
          </limit>
          <dynamics>
            <spring_reference>0</spring_reference>
            <spring_stiffness>0</spring_stiffness>
          </dynamics>
        </axis>
      </joint>
      <link name='right_upper_arm_bottom'>
        <pose relative_to='right_upper_arm_bottom_joint'>0 0 0 0 -0 0</pose>
        <inertial>
          <pose>0 0 0 0 -0 0</pose>
          <mass>0.5</mass>
          <inertia>
            <ixx>0.00281417</ixx>
            <ixy>0</ixy>
            <ixz>0</ixz>
            <iyy>0.00281417</iyy>
            <iyz>0</iyz>
            <izz>0.000252016</izz>
          </inertia>
        </inertial>
        <collision name='right_upper_arm_bottom_collision'>
          <pose>0 0 0 0 -0 0</pose>
          <geometry>
            <mesh>
              <scale>1 1 1</scale>
              <uri>/home/tuttu/ros_ws/src/pluto/models/UpperArmBottom.dae</uri>
            </mesh>
          </geometry>
          <max_contacts>10</max_contacts>
          <surface>
            <contact>
              <ode/>
            </contact>
            <bounce/>
            <friction>
              <torsional>
                <ode/>
              </torsional>
              <ode/>
            </friction>
          </surface>
        </collision>
        <visual name='right_upper_arm_bottom_visual'>
          <pose>0 0 0 0 -0 0</pose>
          <geometry>
            <mesh>
              <scale>1 1 1</scale>
              <uri>/home/tuttu/ros_ws/src/pluto/models/UpperArmBottom.dae</uri>
            </mesh>
          </geometry>
        </visual>
        <self_collide>0</self_collide>
        <enable_wind>0</enable_wind>
        <kinematic>0</kinematic>
      </link>
      <joint name='right_upper_arm_top_joint' type='revolute'>
        <pose relative_to='right_upper_arm_bottom'>0 0 -0.03125 0 -0 0</pose>
        <parent>right_upper_arm_bottom</parent>
        <child>right_upper_arm_top</child>
        <axis>
          <xyz>0 0 1</xyz>
          <limit>
            <lower>-1.79769e+308</lower>
            <upper>1.79769e+308</upper>
            <effort>1</effort>
            <velocity>1</velocity>
          </limit>
          <dynamics>
            <spring_reference>0</spring_reference>
            <spring_stiffness>0</spring_stiffness>
          </dynamics>
        </axis>
      </joint>
      <link name='right_upper_arm_top'>
        <pose relative_to='right_upper_arm_top_joint'>0 0 0 0 -0 0</pose>
        <inertial>
          <pose>0 0 0 0 -0 0</pose>
          <mass>4</mass>
          <inertia>
            <ixx>0.0225134</ixx>
            <ixy>0</ixy>
            <ixz>0</ixz>
            <iyy>0.0225134</iyy>
            <iyz>0</iyz>
            <izz>0.00201613</izz>
          </inertia>
        </inertial>
        <collision name='right_upper_arm_top_collision'>
          <pose>0 0 0 0 -0 0</pose>
          <geometry>
            <mesh>
              <scale>1 1 1</scale>
              <uri>/home/tuttu/ros_ws/src/pluto/models/UpperArmTop.dae</uri>
            </mesh>
          </geometry>
          <max_contacts>10</max_contacts>
          <surface>
            <contact>
              <ode/>
            </contact>
            <bounce/>
            <friction>
              <torsional>
                <ode/>
              </torsional>
              <ode/>
            </friction>
          </surface>
        </collision>
        <visual name='right_upper_arm_top_visual'>
          <pose>0 0 0 0 -0 0</pose>
          <geometry>
            <mesh>
              <scale>1 1 1</scale>
              <uri>/home/tuttu/ros_ws/src/pluto/models/UpperArmTop.dae</uri>
            </mesh>
          </geometry>
        </visual>
        <self_collide>0</self_collide>
        <enable_wind>0</enable_wind>
        <kinematic>0</kinematic>
      </link>
      <joint name='right_forearm_bottom_joint' type='revolute'>
        <pose relative_to='right_upper_arm_top'>0 0 -0.07625 3.14159 1.57079 3.14159</pose>
        <parent>right_upper_arm_top</parent>
        <child>right_forearm_bottom</child>
        <axis>
          <xyz>0 1 0</xyz>
          <limit>
            <lower>-1.79769e+308</lower>
            <upper>1.79769e+308</upper>
            <effort>10</effort>
            <velocity>1</velocity>
          </limit>
          <dynamics>
            <spring_reference>0</spring_reference>
            <spring_stiffness>0</spring_stiffness>
          </dynamics>
        </axis>
      </joint>
      <link name='right_forearm_bottom'>
        <pose relative_to='right_forearm_bottom_joint'>0 0 0 0 -0 0</pose>
        <inertial>
          <pose>0 0 0 0 -0 0</pose>
          <mass>0.5</mass>
          <inertia>
            <ixx>0.000556114</ixx>
            <ixy>0</ixy>
            <ixz>0</ixz>
            <iyy>0.000556114</iyy>
            <iyz>0</iyz>
            <izz>0.000252016</izz>
          </inertia>
        </inertial>
        <collision name='right_forearm_bottom_collision'>
          <pose>0 0 0 0 -0 0</pose>
          <geometry>
            <mesh>
              <scale>1 1 1</scale>
              <uri>/home/tuttu/ros_ws/src/pluto/models/ForearmBottom.dae</uri>
            </mesh>
          </geometry>
          <max_contacts>10</max_contacts>
          <surface>
            <contact>
              <ode/>
            </contact>
            <bounce/>
            <friction>
              <torsional>
                <ode/>
              </torsional>
              <ode/>
            </friction>
          </surface>
        </collision>
        <visual name='right_forearm_bottom_visual'>
          <pose>0 0 0 0 -0 0</pose>
          <geometry>
            <mesh>
              <scale>1 1 1</scale>
              <uri>/home/tuttu/ros_ws/src/pluto/models/ForearmBottom.dae</uri>
            </mesh>
          </geometry>
        </visual>
        <self_collide>0</self_collide>
        <enable_wind>0</enable_wind>
        <kinematic>0</kinematic>
      </link>
      <joint name='right_forearm_top_joint' type='revolute'>
        <pose relative_to='right_forearm_bottom'>0.029 0 0 0 -0 0</pose>
        <parent>right_forearm_bottom</parent>
        <child>right_forearm_top</child>
        <axis>
          <xyz>1 0 0</xyz>
          <limit>
            <lower>-1.79769e+308</lower>
            <upper>1.79769e+308</upper>
            <effort>1</effort>
            <velocity>1</velocity>
          </limit>
          <dynamics>
            <spring_reference>0</spring_reference>
            <spring_stiffness>0</spring_stiffness>
          </dynamics>
        </axis>
      </joint>
      <link name='right_forearm_top'>
        <pose relative_to='right_forearm_top_joint'>0 0 0 0 -0 0</pose>
        <inertial>
          <pose>0 0 0 0 -0 0</pose>
          <mass>0.4</mass>
          <inertia>
            <ixx>0.000444892</ixx>
            <ixy>0</ixy>
            <ixz>0</ixz>
            <iyy>0.000444892</iyy>
            <iyz>0</iyz>
            <izz>0.000201613</izz>
          </inertia>
        </inertial>
        <collision name='right_forearm_top_collision'>
          <pose>0 0 0 0 -0 0</pose>
          <geometry>
            <mesh>
              <scale>1 1 1</scale>
              <uri>/home/tuttu/ros_ws/src/pluto/models/ForearmTop.dae</uri>
            </mesh>
          </geometry>
          <max_contacts>10</max_contacts>
          <surface>
            <contact>
              <ode/>
            </contact>
            <bounce/>
            <friction>
              <torsional>
                <ode/>
              </torsional>
              <ode/>
            </friction>
          </surface>
        </collision>
        <visual name='right_forearm_top_visual'>
          <pose>0 0 0 0 -0 0</pose>
          <geometry>
            <mesh>
              <scale>1 1 1</scale>
              <uri>/home/tuttu/ros_ws/src/pluto/models/ForearmTop.dae</uri>
            </mesh>
          </geometry>
        </visual>
        <self_collide>0</self_collide>
        <enable_wind>0</enable_wind>
        <kinematic>0</kinematic>
      </link>
      <joint name='right_palm_joint' type='revolute'>
        <pose relative_to='right_forearm_top'>0.06525 0 0 0 -0 0</pose>
        <parent>right_forearm_top</parent>
        <child>right_palm</child>
        <axis>
          <xyz>0 0 1</xyz>
          <limit>
            <lower>-1.79769e+308</lower>
            <upper>1.79769e+308</upper>
            <effort>1</effort>
            <velocity>1</velocity>
          </limit>
          <dynamics>
            <spring_reference>0</spring_reference>
            <spring_stiffness>0</spring_stiffness>
          </dynamics>
        </axis>
      </joint>
      <link name='right_palm'>
        <pose relative_to='right_palm_joint'>0 0 0 0 -0 0</pose>
        <inertial>
          <pose>0.00025 0.000172 0 0 -0 0</pose>
          <mass>0.32</mass>
          <inertia>
            <ixx>0.000447453</ixx>
            <ixy>-2.0625e-07</ixy>
            <ixz>0</ixz>
            <iyy>0.000860513</iyy>
            <iyz>0</iyz>
            <izz>0.000447753</izz>
          </inertia>
        </inertial>
        <collision name='right_palm_collision'>
          <pose>0 0 0 0 -0 0</pose>
          <geometry>
            <mesh>
              <scale>1 1 1</scale>
              <uri>/home/tuttu/ros_ws/src/pluto/models/RightPalm.dae</uri>
            </mesh>
          </geometry>
          <max_contacts>10</max_contacts>
          <surface>
            <contact>
              <ode/>
            </contact>
            <bounce/>
            <friction>
              <torsional>
                <ode/>
              </torsional>
              <ode/>
            </friction>
          </surface>
        </collision>
        <collision name='right_palm_surface_collision_1'>
          <pose>0.004 0.00275 0 0 -0 0</pose>
          <geometry>
            <mesh>
              <scale>1 1 1</scale>
              <uri>/home/tuttu/ros_ws/src/pluto/models/RightPalmSurface.dae</uri>
            </mesh>
          </geometry>
          <max_contacts>10</max_contacts>
          <surface>
            <contact>
              <ode/>
            </contact>
            <bounce/>
            <friction>
              <torsional>
                <ode/>
              </torsional>
              <ode/>
            </friction>
          </surface>
        </collision>
        <visual name='right_palm_visual'>
          <pose>0 0 0 0 -0 0</pose>
          <geometry>
            <mesh>
              <scale>1 1 1</scale>
              <uri>/home/tuttu/ros_ws/src/pluto/models/RightPalm.dae</uri>
            </mesh>
          </geometry>
        </visual>
        <visual name='right_palm_surface_visual_1'>
          <pose>0.004 0.00275 0 0 -0 0</pose>
          <geometry>
            <mesh>
              <scale>1 1 1</scale>
              <uri>/home/tuttu/ros_ws/src/pluto/models/RightPalmSurface.dae</uri>
            </mesh>
          </geometry>
        </visual>
        <self_collide>0</self_collide>
        <enable_wind>0</enable_wind>
        <kinematic>0</kinematic>
      </link>
      <joint name='right_index_bottom_joint' type='revolute'>
        <pose relative_to='right_palm'>0.0395 -0.0025 0.0132 0 -0 0</pose>
        <parent>right_palm</parent>
        <child>right_index_bottom</child>
        <axis>
          <xyz>0 0 1</xyz>
          <limit>
            <lower>-1.79769e+308</lower>
            <upper>1.79769e+308</upper>
            <effort>1</effort>
            <velocity>1</velocity>
          </limit>
          <dynamics>
            <spring_reference>0</spring_reference>
            <spring_stiffness>0</spring_stiffness>
          </dynamics>
        </axis>
      </joint>
      <link name='right_index_bottom'>
        <pose relative_to='right_index_bottom_joint'>0 0 0 0 -0 0</pose>
        <inertial>
          <pose>0 0 0 0 -0 0</pose>
          <mass>0.02</mass>
          <inertia>
            <ixx>4.50268e-06</ixx>
            <ixy>0</ixy>
            <ixz>0</ixz>
            <iyy>4.50268e-06</iyy>
            <iyz>0</iyz>
            <izz>4.03225e-07</izz>
          </inertia>
        </inertial>
        <collision name='right_index_bottom_collision'>
          <pose>0 0 0 0 -0 0</pose>
          <geometry>
            <mesh>
              <scale>1 1 1</scale>
              <uri>/home/tuttu/ros_ws/src/pluto/models/IndexBottom.dae</uri>
            </mesh>
          </geometry>
          <max_contacts>10</max_contacts>
          <surface>
            <contact>
              <ode/>
            </contact>
            <bounce/>
            <friction>
              <torsional>
                <ode/>
              </torsional>
              <ode/>
            </friction>
          </surface>
        </collision>
        <visual name='right_index_bottom_visual'>
          <pose>0 0 0 0 -0 0</pose>
          <geometry>
            <mesh>
              <scale>1 1 1</scale>
              <uri>/home/tuttu/ros_ws/src/pluto/models/IndexBottom.dae</uri>
            </mesh>
          </geometry>
        </visual>
        <self_collide>0</self_collide>
        <enable_wind>0</enable_wind>
        <kinematic>0</kinematic>
      </link>
      <joint name='right_index_top_joint' type='revolute'>
        <pose relative_to='right_index_bottom'>0.019 -0.001 0 0 -0 0</pose>
        <parent>right_index_bottom</parent>
        <child>right_index_top</child>
        <axis>
          <xyz>0 0 1</xyz>
          <limit>
            <lower>-1.79769e+308</lower>
            <upper>1.79769e+308</upper>
            <effort>1</effort>
            <velocity>1</velocity>
          </limit>
          <dynamics>
            <spring_reference>0</spring_reference>
            <spring_stiffness>0</spring_stiffness>
          </dynamics>
        </axis>
      </joint>
      <link name='right_index_top'>
        <pose relative_to='right_index_top_joint'>0 0 0 0 -0 0</pose>
        <inertial>
          <pose>0 0 0 0 -0 0</pose>
          <mass>0.02</mass>
          <inertia>
            <ixx>4.50268e-06</ixx>
            <ixy>0</ixy>
            <ixz>0</ixz>
            <iyy>4.50268e-06</iyy>
            <iyz>0</iyz>
            <izz>4.03225e-07</izz>
          </inertia>
        </inertial>
        <collision name='right_index_top_collision'>
          <pose>0 0 0 0 -0 0</pose>
          <geometry>
            <mesh>
              <scale>1 1 1</scale>
              <uri>/home/tuttu/ros_ws/src/pluto/models/IndexTop.dae</uri>
            </mesh>
          </geometry>
          <max_contacts>10</max_contacts>
          <surface>
            <contact>
              <ode/>
            </contact>
            <bounce/>
            <friction>
              <torsional>
                <ode/>
              </torsional>
              <ode/>
            </friction>
          </surface>
        </collision>
        <visual name='right_index_top_visual'>
          <pose>0 0 0 0 -0 0</pose>
          <geometry>
            <mesh>
              <scale>1 1 1</scale>
              <uri>/home/tuttu/ros_ws/src/pluto/models/IndexTop.dae</uri>
            </mesh>
          </geometry>
        </visual>
        <self_collide>0</self_collide>
        <enable_wind>0</enable_wind>
        <kinematic>0</kinematic>
      </link>
      <joint name='right_middle_bottom_joint' type='revolute'>
        <pose relative_to='right_palm'>0.0395 -0.00325 0.00425 0 -0 0</pose>
        <parent>right_palm</parent>
        <child>right_middle_bottom</child>
        <axis>
          <xyz>0 0 1</xyz>
          <limit>
            <lower>-1.79769e+308</lower>
            <upper>1.79769e+308</upper>
            <effort>1</effort>
            <velocity>1</velocity>
          </limit>
          <dynamics>
            <spring_reference>0</spring_reference>
            <spring_stiffness>0</spring_stiffness>
          </dynamics>
        </axis>
      </joint>
      <link name='right_middle_bottom'>
        <pose relative_to='right_middle_bottom_joint'>0 0 0 0 -0 0</pose>
        <inertial>
          <pose>0 0 0 0 -0 0</pose>
          <mass>0.02</mass>
          <inertia>
            <ixx>4.50268e-06</ixx>
            <ixy>0</ixy>
            <ixz>0</ixz>
            <iyy>4.50268e-06</iyy>
            <iyz>0</iyz>
            <izz>4.03225e-07</izz>
          </inertia>
        </inertial>
        <collision name='right_middle_bottom_collision'>
          <pose>0 0 0 0 -0 0</pose>
          <geometry>
            <mesh>
              <scale>1 1 1</scale>
              <uri>/home/tuttu/ros_ws/src/pluto/models/MiddleBottom.dae</uri>
            </mesh>
          </geometry>
          <max_contacts>10</max_contacts>
          <surface>
            <contact>
              <ode/>
            </contact>
            <bounce/>
            <friction>
              <torsional>
                <ode/>
              </torsional>
              <ode/>
            </friction>
          </surface>
        </collision>
        <visual name='right_middle_bottom_visual'>
          <pose>0 0 0 0 -0 0</pose>
          <geometry>
            <mesh>
              <scale>1 1 1</scale>
              <uri>/home/tuttu/ros_ws/src/pluto/models/MiddleBottom.dae</uri>
            </mesh>
          </geometry>
        </visual>
        <self_collide>0</self_collide>
        <enable_wind>0</enable_wind>
        <kinematic>0</kinematic>
      </link>
      <joint name='right_middle_top_joint' type='revolute'>
        <pose relative_to='right_middle_bottom'>0.0205 0 -0.0002 0 -0 0</pose>
        <parent>right_middle_bottom</parent>
        <child>right_middle_top</child>
        <axis>
          <xyz>0 0 1</xyz>
          <limit>
            <lower>-1.79769e+308</lower>
            <upper>1.79769e+308</upper>
            <effort>1</effort>
            <velocity>1</velocity>
          </limit>
          <dynamics>
            <spring_reference>0</spring_reference>
            <spring_stiffness>0</spring_stiffness>
          </dynamics>
        </axis>
      </joint>
      <link name='right_middle_top'>
        <pose relative_to='right_middle_top_joint'>0 0 0 0 -0 0</pose>
        <inertial>
          <pose>0 0 0 0 -0 0</pose>
          <mass>0.02</mass>
          <inertia>
            <ixx>4.50268e-06</ixx>
            <ixy>0</ixy>
            <ixz>0</ixz>
            <iyy>4.50268e-06</iyy>
            <iyz>0</iyz>
            <izz>4.03225e-07</izz>
          </inertia>
        </inertial>
        <collision name='right_middle_top_collision'>
          <pose>0 0 0 0 -0 0</pose>
          <geometry>
            <mesh>
              <scale>1 1 1</scale>
              <uri>/home/tuttu/ros_ws/src/pluto/models/MiddleTop.dae</uri>
            </mesh>
          </geometry>
          <max_contacts>10</max_contacts>
          <surface>
            <contact>
              <ode/>
            </contact>
            <bounce/>
            <friction>
              <torsional>
                <ode/>
              </torsional>
              <ode/>
            </friction>
          </surface>
        </collision>
        <visual name='right_middle_top_visual'>
          <pose>0 0 0 0 -0 0</pose>
          <geometry>
            <mesh>
              <scale>1 1 1</scale>
              <uri>/home/tuttu/ros_ws/src/pluto/models/MiddleTop.dae</uri>
            </mesh>
          </geometry>
        </visual>
        <self_collide>0</self_collide>
        <enable_wind>0</enable_wind>
        <kinematic>0</kinematic>
      </link>
      <joint name='right_pinky_bottom_joint' type='revolute'>
        <pose relative_to='right_palm'>0.0395 -0.00325 -0.0125 0 -0 0</pose>
        <parent>right_palm</parent>
        <child>right_pinky_bottom</child>
        <axis>
          <xyz>0 0 1</xyz>
          <limit>
            <lower>-1.79769e+308</lower>
            <upper>1.79769e+308</upper>
            <effort>1</effort>
            <velocity>1</velocity>
          </limit>
          <dynamics>
            <spring_reference>0</spring_reference>
            <spring_stiffness>0</spring_stiffness>
          </dynamics>
        </axis>
      </joint>
      <link name='right_pinky_bottom'>
        <pose relative_to='right_pinky_bottom_joint'>0 0 0 0 -0 0</pose>
        <inertial>
          <pose>0 0 0 0 -0 0</pose>
          <mass>0.02</mass>
          <inertia>
            <ixx>4.50268e-06</ixx>
            <ixy>0</ixy>
            <ixz>0</ixz>
            <iyy>4.50268e-06</iyy>
            <iyz>0</iyz>
            <izz>4.03225e-07</izz>
          </inertia>
        </inertial>
        <collision name='right_pinky_bottom_collision'>
          <pose>0 0 0 0 -0 0</pose>
          <geometry>
            <mesh>
              <scale>1 1 1</scale>
              <uri>/home/tuttu/ros_ws/src/pluto/models/PinkyBottom.dae</uri>
            </mesh>
          </geometry>
          <max_contacts>10</max_contacts>
          <surface>
            <contact>
              <ode/>
            </contact>
            <bounce/>
            <friction>
              <torsional>
                <ode/>
              </torsional>
              <ode/>
            </friction>
          </surface>
        </collision>
        <visual name='right_pinky_bottom_visual'>
          <pose>0 0 0 0 -0 0</pose>
          <geometry>
            <mesh>
              <scale>1 1 1</scale>
              <uri>/home/tuttu/ros_ws/src/pluto/models/PinkyBottom.dae</uri>
            </mesh>
          </geometry>
        </visual>
        <self_collide>0</self_collide>
        <enable_wind>0</enable_wind>
        <kinematic>0</kinematic>
      </link>
      <joint name='right_pinky_top_joint' type='revolute'>
        <pose relative_to='right_pinky_bottom'>0.0145 0.00025 0.0002 0 -0 0</pose>
        <parent>right_pinky_bottom</parent>
        <child>right_pinky_top</child>
        <axis>
          <xyz>0 0 1</xyz>
          <limit>
            <lower>-1.79769e+308</lower>
            <upper>1.79769e+308</upper>
            <effort>1</effort>
            <velocity>1</velocity>
          </limit>
          <dynamics>
            <spring_reference>0</spring_reference>
            <spring_stiffness>0</spring_stiffness>
          </dynamics>
        </axis>
      </joint>
      <link name='right_pinky_top'>
        <pose relative_to='right_pinky_top_joint'>0 0 0 0 -0 0</pose>
        <inertial>
          <pose>0 0 0 0 -0 0</pose>
          <mass>0.02</mass>
          <inertia>
            <ixx>4.50268e-06</ixx>
            <ixy>0</ixy>
            <ixz>0</ixz>
            <iyy>4.50268e-06</iyy>
            <iyz>0</iyz>
            <izz>4.03225e-07</izz>
          </inertia>
        </inertial>
        <collision name='right_pinky_top_collision'>
          <pose>0 0 0 0 -0 0</pose>
          <geometry>
            <mesh>
              <scale>1 1 1</scale>
              <uri>/home/tuttu/ros_ws/src/pluto/models/PinkyTop.dae</uri>
            </mesh>
          </geometry>
          <max_contacts>10</max_contacts>
          <surface>
            <contact>
              <ode/>
            </contact>
            <bounce/>
            <friction>
              <torsional>
                <ode/>
              </torsional>
              <ode/>
            </friction>
          </surface>
        </collision>
        <visual name='right_pinky_top_visual'>
          <pose>0 0 0 0 -0 0</pose>
          <geometry>
            <mesh>
              <scale>1 1 1</scale>
              <uri>/home/tuttu/ros_ws/src/pluto/models/PinkyTop.dae</uri>
            </mesh>
          </geometry>
        </visual>
        <self_collide>0</self_collide>
        <enable_wind>0</enable_wind>
        <kinematic>0</kinematic>
      </link>
      <joint name='right_ring_bottom_joint' type='revolute'>
        <pose relative_to='right_palm'>0.0395 -0.00325 -0.00425 0 -0 0</pose>
        <parent>right_palm</parent>
        <child>right_ring_bottom</child>
        <axis>
          <xyz>0 0 1</xyz>
          <limit>
            <lower>-1.79769e+308</lower>
            <upper>1.79769e+308</upper>
            <effort>1</effort>
            <velocity>1</velocity>
          </limit>
          <dynamics>
            <spring_reference>0</spring_reference>
            <spring_stiffness>0</spring_stiffness>
          </dynamics>
        </axis>
      </joint>
      <link name='right_ring_bottom'>
        <pose relative_to='right_ring_bottom_joint'>0 0 0 0 -0 0</pose>
        <inertial>
          <pose>0 0 0 0 -0 0</pose>
          <mass>0.02</mass>
          <inertia>
            <ixx>4.50268e-06</ixx>
            <ixy>0</ixy>
            <ixz>0</ixz>
            <iyy>4.50268e-06</iyy>
            <iyz>0</iyz>
            <izz>4.03225e-07</izz>
          </inertia>
        </inertial>
        <collision name='right_ring_bottom_collision'>
          <pose>0 0 0 0 -0 0</pose>
          <geometry>
            <mesh>
              <scale>1 1 1</scale>
              <uri>/home/tuttu/ros_ws/src/pluto/models/RingBottom.dae</uri>
            </mesh>
          </geometry>
          <max_contacts>10</max_contacts>
          <surface>
            <contact>
              <ode/>
            </contact>
            <bounce/>
            <friction>
              <torsional>
                <ode/>
              </torsional>
              <ode/>
            </friction>
          </surface>
        </collision>
        <visual name='right_ring_bottom_visual'>
          <pose>0 0 0 0 -0 0</pose>
          <geometry>
            <mesh>
              <scale>1 1 1</scale>
              <uri>/home/tuttu/ros_ws/src/pluto/models/RingBottom.dae</uri>
            </mesh>
          </geometry>
        </visual>
        <self_collide>0</self_collide>
        <enable_wind>0</enable_wind>
        <kinematic>0</kinematic>
      </link>
      <joint name='right_ring_top_joint' type='revolute'>
        <pose relative_to='right_ring_bottom'>0.019 0.0005 0.0002 0 -0 0</pose>
        <parent>right_ring_bottom</parent>
        <child>right_ring_top</child>
        <axis>
          <xyz>0 0 1</xyz>
          <limit>
            <lower>-1.79769e+308</lower>
            <upper>1.79769e+308</upper>
            <effort>1</effort>
            <velocity>1</velocity>
          </limit>
          <dynamics>
            <spring_reference>0</spring_reference>
            <spring_stiffness>0</spring_stiffness>
          </dynamics>
        </axis>
      </joint>
      <link name='right_ring_top'>
        <pose relative_to='right_ring_top_joint'>0 0 0 0 -0 0</pose>
        <inertial>
          <pose>0 0 0 0 -0 0</pose>
          <mass>0.02</mass>
          <inertia>
            <ixx>4.50268e-06</ixx>
            <ixy>0</ixy>
            <ixz>0</ixz>
            <iyy>4.50268e-06</iyy>
            <iyz>0</iyz>
            <izz>4.03225e-07</izz>
          </inertia>
        </inertial>
        <collision name='right_ring_top_collision'>
          <pose>0 0 0 0 -0 0</pose>
          <geometry>
            <mesh>
              <scale>1 1 1</scale>
              <uri>/home/tuttu/ros_ws/src/pluto/models/RingTop.dae</uri>
            </mesh>
          </geometry>
          <max_contacts>10</max_contacts>
          <surface>
            <contact>
              <ode/>
            </contact>
            <bounce/>
            <friction>
              <torsional>
                <ode/>
              </torsional>
              <ode/>
            </friction>
          </surface>
        </collision>
        <visual name='right_ring_top_visual'>
          <pose>0 0 0 0 -0 0</pose>
          <geometry>
            <mesh>
              <scale>1 1 1</scale>
              <uri>/home/tuttu/ros_ws/src/pluto/models/RingTop.dae</uri>
            </mesh>
          </geometry>
        </visual>
        <self_collide>0</self_collide>
        <enable_wind>0</enable_wind>
        <kinematic>0</kinematic>
      </link>
      <joint name='right_thumb_piece_joint' type='revolute'>
        <pose relative_to='right_palm'>0.0135 -0.002 0.0125 0 -0 0</pose>
        <parent>right_palm</parent>
        <child>right_thumb_piece</child>
        <axis>
          <xyz>1 0 0</xyz>
          <limit>
            <lower>-1.79769e+308</lower>
            <upper>1.79769e+308</upper>
            <effort>1</effort>
            <velocity>1</velocity>
          </limit>
          <dynamics>
            <spring_reference>0</spring_reference>
            <spring_stiffness>0</spring_stiffness>
          </dynamics>
        </axis>
      </joint>
      <link name='right_thumb_piece'>
        <pose relative_to='right_thumb_piece_joint'>0 0 0 0 -0 0</pose>
        <inertial>
          <pose>0 0 0 0 -0 0</pose>
          <mass>0.1</mass>
          <inertia>
            <ixx>2.68817e-05</ixx>
            <ixy>0</ixy>
            <ixz>0</ixz>
            <iyy>4.30107e-05</iyy>
            <iyz>0</iyz>
            <izz>2.68817e-05</izz>
          </inertia>
        </inertial>
        <collision name='right_thumb_piece_collision'>
          <pose>0 0 0 0 -0 0</pose>
          <geometry>
            <mesh>
              <scale>1 1 1</scale>
              <uri>/home/tuttu/ros_ws/src/pluto/models/RightThumbPiece.dae</uri>
            </mesh>
          </geometry>
          <max_contacts>10</max_contacts>
          <surface>
            <contact>
              <ode/>
            </contact>
            <bounce/>
            <friction>
              <torsional>
                <ode/>
              </torsional>
              <ode/>
            </friction>
          </surface>
        </collision>
        <visual name='right_thumb_piece_visual'>
          <pose>0 0 0 0 -0 0</pose>
          <geometry>
            <mesh>
              <scale>1 1 1</scale>
              <uri>/home/tuttu/ros_ws/src/pluto/models/RightThumbPiece.dae</uri>
            </mesh>
          </geometry>
        </visual>
        <self_collide>0</self_collide>
        <enable_wind>0</enable_wind>
        <kinematic>0</kinematic>
      </link>
      <joint name='right_thumb_bottom_joint' type='revolute'>
        <pose relative_to='right_thumb_piece'>0.0035 -0.00025 0.011 0 -0 0</pose>
        <parent>right_thumb_piece</parent>
        <child>right_thumb_bottom</child>
        <axis>
          <xyz>0 1 0</xyz>
          <limit>
            <lower>-1.79769e+308</lower>
            <upper>1.79769e+308</upper>
            <effort>1</effort>
            <velocity>1</velocity>
          </limit>
          <dynamics>
            <spring_reference>0</spring_reference>
            <spring_stiffness>0</spring_stiffness>
          </dynamics>
        </axis>
      </joint>
      <link name='right_thumb_bottom'>
        <pose relative_to='right_thumb_bottom_joint'>0 0 0 0 -0 0</pose>
        <inertial>
          <pose>0 0 0 0 -0 0</pose>
          <mass>0.02</mass>
          <inertia>
            <ixx>4.50268e-06</ixx>
            <ixy>0</ixy>
            <ixz>0</ixz>
            <iyy>4.50268e-06</iyy>
            <iyz>0</iyz>
            <izz>4.03225e-07</izz>
          </inertia>
        </inertial>
        <collision name='right_thumb_bottom_collision'>
          <pose>0 0 0 0.314159 -0 0.523599</pose>
          <geometry>
            <mesh>
              <scale>1 1 1</scale>
              <uri>/home/tuttu/ros_ws/src/pluto/models/ThumbBottom.dae</uri>
            </mesh>
          </geometry>
          <max_contacts>10</max_contacts>
          <surface>
            <contact>
              <ode/>
            </contact>
            <bounce/>
            <friction>
              <torsional>
                <ode/>
              </torsional>
              <ode/>
            </friction>
          </surface>
        </collision>
        <visual name='right_thumb_bottom_visual'>
          <pose>0 0 0 0.314159 -0 0.523599</pose>
          <geometry>
            <mesh>
              <scale>1 1 1</scale>
              <uri>/home/tuttu/ros_ws/src/pluto/models/ThumbBottom.dae</uri>
            </mesh>
          </geometry>
        </visual>
        <self_collide>0</self_collide>
        <enable_wind>0</enable_wind>
        <kinematic>0</kinematic>
      </link>
      <joint name='right_thumb_top_joint' type='revolute'>
        <pose relative_to='right_thumb_bottom'>0.0125 0.0075 0 0 -0 0</pose>
        <parent>right_thumb_bottom</parent>
        <child>right_thumb_top</child>
        <axis>
          <xyz>0 1 0</xyz>
          <limit>
            <lower>-1.79769e+308</lower>
            <upper>1.79769e+308</upper>
            <effort>1</effort>
            <velocity>1</velocity>
          </limit>
          <dynamics>
            <spring_reference>0</spring_reference>
            <spring_stiffness>0</spring_stiffness>
          </dynamics>
        </axis>
      </joint>
      <link name='right_thumb_top'>
        <pose relative_to='right_thumb_top_joint'>0 0 0 0 -0 0</pose>
        <inertial>
          <pose>0 0 0 0 -0 0</pose>
          <mass>0.02</mass>
          <inertia>
            <ixx>4.50268e-06</ixx>
            <ixy>0</ixy>
            <ixz>0</ixz>
            <iyy>4.50268e-06</iyy>
            <iyz>0</iyz>
            <izz>4.03225e-07</izz>
          </inertia>
        </inertial>
        <collision name='right_thumb_top_collision'>
          <pose>0 0 0 0.314159 -0 0.523599</pose>
          <geometry>
            <mesh>
              <scale>1 1 1</scale>
              <uri>/home/tuttu/ros_ws/src/pluto/models/ThumbTop.dae</uri>
            </mesh>
          </geometry>
          <max_contacts>10</max_contacts>
          <surface>
            <contact>
              <ode/>
            </contact>
            <bounce/>
            <friction>
              <torsional>
                <ode/>
              </torsional>
              <ode/>
            </friction>
          </surface>
        </collision>
        <visual name='right_thumb_top_visual'>
          <pose>0 0 0 0.314159 -0 0.523599</pose>
          <geometry>
            <mesh>
              <scale>1 1 1</scale>
              <uri>/home/tuttu/ros_ws/src/pluto/models/ThumbTop.dae</uri>
            </mesh>
          </geometry>
        </visual>
        <self_collide>0</self_collide>
        <enable_wind>0</enable_wind>
        <kinematic>0</kinematic>
      </link>
      <static>0</static>
      <plugin name='differential_drive_controller' filename='libgazebo_ros_diff_drive.so'>
        <alwaysOn>0</alwaysOn>
        <legacyMode>0</legacyMode>
        <updateRate>20</updateRate>
        <leftJoint>left_wheel_joint</leftJoint>
        <rightJoint>right_wheel_joint</rightJoint>
        <wheelSeparation>0.5205</wheelSeparation>
        <wheelDiameter>0.2032</wheelDiameter>
        <torque>20</torque>
        <commandTopic>/cmd_vel</commandTopic>
        <odometryTopic>/odom</odometryTopic>
        <odometryFrame>odom</odometryFrame>
        <robotBaseFrame>base_footprint</robotBaseFrame>
        <publishOdom>1</publishOdom>
        <robotNamespace>/</robotNamespace>
      </plugin>
      <pose>0 0 0.5 0 0 -3.14159</pose>
    </model>
    <model name='Basement'>
      <pose>-6.12947 -0.90241 0 0 -0 0</pose>
      <link name='Wall_0'>
        <collision name='Wall_0_Collision'>
          <geometry>
            <box>
              <size>4.876 0.15 2</size>
            </box>
          </geometry>
          <pose>0 0 1 0 -0 0</pose>
          <max_contacts>10</max_contacts>
          <surface>
            <contact>
              <ode/>
            </contact>
            <bounce/>
            <friction>
              <torsional>
                <ode/>
              </torsional>
              <ode/>
            </friction>
          </surface>
        </collision>
        <visual name='Wall_0_Visual'>
          <pose>0 0 1 0 -0 0</pose>
          <geometry>
            <box>
              <size>4.876 0.15 2</size>
            </box>
          </geometry>
          <material>
            <script>
              <uri>file://media/materials/scripts/gazebo.material</uri>
              <name>Gazebo/Grey</name>
            </script>
            <ambient>1 1 1 1</ambient>
          </material>
          <meta>
            <layer>0</layer>
          </meta>
        </visual>
        <pose>7.20212 2.54754 0 0 -0 1.5708</pose>
        <self_collide>0</self_collide>
        <enable_wind>0</enable_wind>
        <kinematic>0</kinematic>
      </link>
      <link name='Wall_10'>
        <collision name='Wall_10_Collision'>
          <geometry>
            <box>
              <size>4.98852 0.15 2</size>
            </box>
          </geometry>
          <pose>0 0 1 0 -0 0</pose>
          <max_contacts>10</max_contacts>
          <surface>
            <contact>
              <ode/>
            </contact>
            <bounce/>
            <friction>
              <torsional>
                <ode/>
              </torsional>
              <ode/>
            </friction>
          </surface>
        </collision>
        <visual name='Wall_10_Visual'>
          <pose>0 0 1 0 -0 0</pose>
          <geometry>
            <box>
              <size>4.98852 0.15 2</size>
            </box>
          </geometry>
          <material>
            <script>
              <uri>file://media/materials/scripts/gazebo.material</uri>
              <name>Gazebo/Grey</name>
            </script>
            <ambient>1 1 1 1</ambient>
          </material>
          <meta>
            <layer>0</layer>
          </meta>
        </visual>
        <pose>5.64804 -2.49054 0 0 -0 -1.58323</pose>
        <self_collide>0</self_collide>
        <enable_wind>0</enable_wind>
        <kinematic>0</kinematic>
      </link>
      <link name='Wall_11'>
        <collision name='Wall_11_Collision'>
          <geometry>
            <box>
              <size>13 0.15 2</size>
            </box>
          </geometry>
          <pose>0 0 1 0 -0 0</pose>
          <max_contacts>10</max_contacts>
          <surface>
            <contact>
              <ode/>
            </contact>
            <bounce/>
            <friction>
              <torsional>
                <ode/>
              </torsional>
              <ode/>
            </friction>
          </surface>
        </collision>
        <visual name='Wall_11_Visual'>
          <pose>0 0 1 0 -0 0</pose>
          <geometry>
            <box>
              <size>13 0.15 2</size>
            </box>
          </geometry>
          <material>
            <script>
              <uri>file://media/materials/scripts/gazebo.material</uri>
              <name>Gazebo/Grey</name>
            </script>
            <ambient>1 1 1 1</ambient>
          </material>
          <meta>
            <layer>0</layer>
          </meta>
        </visual>
        <pose>-0.776956 -4.87954 0 0 -0 3.14159</pose>
        <self_collide>0</self_collide>
        <enable_wind>0</enable_wind>
        <kinematic>0</kinematic>
      </link>
      <link name='Wall_12'>
        <collision name='Wall_12_Collision'>
          <geometry>
            <box>
              <size>4.5 0.15 2</size>
            </box>
          </geometry>
          <pose>0 0 1 0 -0 0</pose>
          <max_contacts>10</max_contacts>
          <surface>
            <contact>
              <ode/>
            </contact>
            <bounce/>
            <friction>
              <torsional>
                <ode/>
              </torsional>
              <ode/>
            </friction>
          </surface>
        </collision>
        <visual name='Wall_12_Visual'>
          <pose>0 0 1 0 -0 0</pose>
          <geometry>
            <box>
              <size>4.5 0.15 2</size>
            </box>
          </geometry>
          <material>
            <script>
              <uri>file://media/materials/scripts/gazebo.material</uri>
              <name>Gazebo/Grey</name>
            </script>
            <ambient>1 1 1 1</ambient>
          </material>
          <meta>
            <layer>0</layer>
          </meta>
        </visual>
        <pose>-7.20196 -2.70454 0 0 -0 1.5708</pose>
        <self_collide>0</self_collide>
        <enable_wind>0</enable_wind>
        <kinematic>0</kinematic>
      </link>
      <link name='Wall_15'>
        <collision name='Wall_15_Collision'>
          <geometry>
            <box>
              <size>5.5 0.15 2</size>
            </box>
          </geometry>
          <pose>0 0 1 0 -0 0</pose>
          <max_contacts>10</max_contacts>
          <surface>
            <contact>
              <ode/>
            </contact>
            <bounce/>
            <friction>
              <torsional>
                <ode/>
              </torsional>
              <ode/>
            </friction>
          </surface>
        </collision>
        <visual name='Wall_15_Visual'>
          <pose>0 0 1 0 -0 0</pose>
          <geometry>
            <box>
              <size>5.5 0.15 2</size>
            </box>
          </geometry>
          <material>
            <script>
              <uri>file://media/materials/scripts/gazebo.material</uri>
              <name>Gazebo/Grey</name>
            </script>
            <ambient>1 1 1 1</ambient>
          </material>
          <meta>
            <layer>0</layer>
          </meta>
        </visual>
        <pose>-7.20196 2.14546 0 0 -0 1.5708</pose>
        <self_collide>0</self_collide>
        <enable_wind>0</enable_wind>
        <kinematic>0</kinematic>
      </link>
      <link name='Wall_16'>
        <collision name='Wall_16_Collision'>
          <geometry>
            <box>
              <size>3.86008 0.15 2</size>
            </box>
          </geometry>
          <pose>0 0 1 0 -0 0</pose>
          <max_contacts>10</max_contacts>
          <surface>
            <contact>
              <ode/>
            </contact>
            <bounce/>
            <friction>
              <torsional>
                <ode/>
              </torsional>
              <ode/>
            </friction>
          </surface>
        </collision>
        <visual name='Wall_16_Visual'>
          <pose>0 0 1 0 -0 0</pose>
          <geometry>
            <box>
              <size>3.86008 0.15 2</size>
            </box>
          </geometry>
          <material>
            <script>
              <uri>file://media/materials/scripts/gazebo.material</uri>
              <name>Gazebo/Grey</name>
            </script>
            <ambient>1 1 1 1</ambient>
          </material>
          <meta>
            <layer>0</layer>
          </meta>
        </visual>
        <pose>-5.34692 4.8245 0 0 -0 0.002176</pose>
        <self_collide>0</self_collide>
        <enable_wind>0</enable_wind>
        <kinematic>0</kinematic>
      </link>
      <link name='Wall_17'>
        <collision name='Wall_17_Collision'>
          <geometry>
            <box>
              <size>1.626 0.15 2</size>
            </box>
          </geometry>
          <pose>0 0 1 0 -0 0</pose>
          <max_contacts>10</max_contacts>
          <surface>
            <contact>
              <ode/>
            </contact>
            <bounce/>
            <friction>
              <torsional>
                <ode/>
              </torsional>
              <ode/>
            </friction>
          </surface>
        </collision>
        <visual name='Wall_17_Visual'>
          <pose>0 0 1 0 -0 0</pose>
          <geometry>
            <box>
              <size>1.626 0.15 2</size>
            </box>
          </geometry>
          <material>
            <script>
              <uri>file://media/materials/scripts/gazebo.material</uri>
              <name>Gazebo/Grey</name>
            </script>
            <ambient>1 1 1 1</ambient>
          </material>
          <meta>
            <layer>0</layer>
          </meta>
        </visual>
        <pose>-3.49188 4.09054 0 0 -0 -1.5708</pose>
        <self_collide>0</self_collide>
        <enable_wind>0</enable_wind>
        <kinematic>0</kinematic>
      </link>
      <link name='Wall_21'>
        <collision name='Wall_21_Collision'>
          <geometry>
            <box>
              <size>3.5 0.15 2</size>
            </box>
          </geometry>
          <pose>0 0 1 0 -0 0</pose>
          <max_contacts>10</max_contacts>
          <surface>
            <contact>
              <ode/>
            </contact>
            <bounce/>
            <friction>
              <torsional>
                <ode/>
              </torsional>
              <ode/>
            </friction>
          </surface>
        </collision>
        <visual name='Wall_21_Visual'>
          <pose>0 0 1 0 -0 0</pose>
          <geometry>
            <box>
              <size>3.5 0.15 2</size>
            </box>
          </geometry>
          <material>
            <script>
              <uri>file://media/materials/scripts/gazebo.material</uri>
              <name>Gazebo/Grey</name>
            </script>
            <ambient>1 1 1 1</ambient>
          </material>
          <meta>
            <layer>0</layer>
          </meta>
        </visual>
        <pose>-1.81688 3.35254 0 0 -0 0</pose>
        <self_collide>0</self_collide>
        <enable_wind>0</enable_wind>
        <kinematic>0</kinematic>
      </link>
      <link name='Wall_28'>
        <collision name='Wall_28_Collision'>
          <geometry>
            <box>
              <size>3.734 0.15 2</size>
            </box>
          </geometry>
          <pose>0 0 1 0 -0 0</pose>
          <max_contacts>10</max_contacts>
          <surface>
            <contact>
              <ode/>
            </contact>
            <bounce/>
            <friction>
              <torsional>
                <ode/>
              </torsional>
              <ode/>
            </friction>
          </surface>
        </collision>
        <visual name='Wall_28_Visual'>
          <pose>0 0 1 0 -0 0</pose>
          <geometry>
            <box>
              <size>3.734 0.15 2</size>
            </box>
          </geometry>
          <material>
            <script>
              <uri>file://media/materials/scripts/gazebo.material</uri>
              <name>Gazebo/Grey</name>
            </script>
            <ambient>1 1 1 1</ambient>
          </material>
          <meta>
            <layer>0</layer>
          </meta>
        </visual>
        <pose>1.86612 3.11854 0 0 -0 -1.5708</pose>
        <self_collide>0</self_collide>
        <enable_wind>0</enable_wind>
        <kinematic>0</kinematic>
      </link>
      <link name='Wall_30'>
        <collision name='Wall_30_Collision'>
          <geometry>
            <box>
              <size>2 0.15 2</size>
            </box>
          </geometry>
          <pose>0 0 1 0 -0 0</pose>
          <max_contacts>10</max_contacts>
          <surface>
            <contact>
              <ode/>
            </contact>
            <bounce/>
            <friction>
              <torsional>
                <ode/>
              </torsional>
              <ode/>
            </friction>
          </surface>
        </collision>
        <visual name='Wall_30_Visual'>
          <pose>0 0 1 0 -0 0</pose>
          <geometry>
            <box>
              <size>2 0.15 2</size>
            </box>
          </geometry>
          <material>
            <script>
              <uri>file://media/materials/scripts/gazebo.material</uri>
              <name>Gazebo/Grey</name>
            </script>
            <ambient>1 1 1 1</ambient>
          </material>
          <meta>
            <layer>0</layer>
          </meta>
        </visual>
        <pose>0.783119 3.35254 0 0 -0 0</pose>
        <self_collide>0</self_collide>
        <enable_wind>0</enable_wind>
        <kinematic>0</kinematic>
      </link>
      <link name='Wall_32'>
        <collision name='Wall_32_Collision'>
          <geometry>
            <box>
              <size>1.75 0.15 2.5</size>
            </box>
          </geometry>
          <pose>0 0 1.25 0 -0 0</pose>
          <max_contacts>10</max_contacts>
          <surface>
            <contact>
              <ode/>
            </contact>
            <bounce/>
            <friction>
              <torsional>
                <ode/>
              </torsional>
              <ode/>
            </friction>
          </surface>
        </collision>
        <visual name='Wall_32_Visual'>
          <pose>0 0 1.25 0 -0 0</pose>
          <geometry>
            <box>
              <size>1.75 0.15 2.5</size>
            </box>
          </geometry>
          <material>
            <script>
              <uri>file://media/materials/scripts/gazebo.material</uri>
              <name>Gazebo/Grey</name>
            </script>
            <ambient>1 1 1 1</ambient>
          </material>
          <meta>
            <layer>0</layer>
          </meta>
        </visual>
        <pose>0.752479 0.564965 0 0 -0 -1.5708</pose>
        <self_collide>0</self_collide>
        <enable_wind>0</enable_wind>
        <kinematic>0</kinematic>
      </link>
      <link name='Wall_33'>
        <collision name='Wall_33_Collision'>
          <geometry>
            <box>
              <size>5 0.15 2.5</size>
            </box>
          </geometry>
          <pose>0 0 1.25 0 -0 0</pose>
          <max_contacts>10</max_contacts>
          <surface>
            <contact>
              <ode/>
            </contact>
            <bounce/>
            <friction>
              <torsional>
                <ode/>
              </torsional>
              <ode/>
            </friction>
          </surface>
        </collision>
        <visual name='Wall_33_Visual'>
          <pose>0 0 1.25 0 -0 0</pose>
          <geometry>
            <box>
              <size>5 0.15 2.5</size>
            </box>
          </geometry>
          <material>
            <script>
              <uri>file://media/materials/scripts/gazebo.material</uri>
              <name>Gazebo/Grey</name>
            </script>
            <ambient>1 1 1 1</ambient>
          </material>
          <meta>
            <layer>0</layer>
          </meta>
        </visual>
        <pose>-1.67252 -0.235035 0 0 -0 3.14159</pose>
        <self_collide>0</self_collide>
        <enable_wind>0</enable_wind>
        <kinematic>0</kinematic>
      </link>
      <link name='Wall_34'>
        <collision name='Wall_34_Collision'>
          <geometry>
            <box>
              <size>1.33104 0.15 2.5</size>
            </box>
          </geometry>
          <pose>0 0 1.25 0 -0 0</pose>
          <max_contacts>10</max_contacts>
          <surface>
            <contact>
              <ode/>
            </contact>
            <bounce/>
            <friction>
              <torsional>
                <ode/>
              </torsional>
              <ode/>
            </friction>
          </surface>
        </collision>
        <visual name='Wall_34_Visual'>
          <pose>0 0 1.25 0 -0 0</pose>
          <geometry>
            <box>
              <size>1.33104 0.15 2.5</size>
            </box>
          </geometry>
          <material>
            <script>
              <uri>file://media/materials/scripts/gazebo.material</uri>
              <name>Gazebo/Grey</name>
            </script>
            <ambient>1 1 1 1</ambient>
          </material>
          <meta>
            <layer>0</layer>
          </meta>
        </visual>
        <pose>-4.44087 0.245406 0 0 -0 2.19129</pose>
        <self_collide>0</self_collide>
        <enable_wind>0</enable_wind>
        <kinematic>0</kinematic>
      </link>
      <link name='Wall_35'>
        <collision name='Wall_35_Collision'>
          <geometry>
            <box>
              <size>0.75 0.15 2.5</size>
            </box>
          </geometry>
          <pose>0 0 1.25 0 -0 0</pose>
          <max_contacts>10</max_contacts>
          <surface>
            <contact>
              <ode/>
            </contact>
            <bounce/>
            <friction>
              <torsional>
                <ode/>
              </torsional>
              <ode/>
            </friction>
          </surface>
        </collision>
        <visual name='Wall_35_Visual'>
          <pose>0 0 1.25 0 -0 0</pose>
          <geometry>
            <box>
              <size>0.75 0.15 2.5</size>
            </box>
          </geometry>
          <material>
            <script>
              <uri>file://media/materials/scripts/gazebo.material</uri>
              <name>Gazebo/Grey</name>
            </script>
            <ambient>1 1 1 1</ambient>
          </material>
          <meta>
            <layer>0</layer>
          </meta>
        </visual>
        <pose>-5.08422 0.725847 0 0 -0 3.14159</pose>
        <self_collide>0</self_collide>
        <enable_wind>0</enable_wind>
        <kinematic>0</kinematic>
      </link>
      <link name='Wall_37'>
        <collision name='Wall_37_Collision'>
          <geometry>
            <box>
              <size>1.95373 0.15 2.5</size>
            </box>
          </geometry>
          <pose>0 0 1.25 0 -0 0</pose>
          <max_contacts>10</max_contacts>
          <surface>
            <contact>
              <ode/>
            </contact>
            <bounce/>
            <friction>
              <torsional>
                <ode/>
              </torsional>
              <ode/>
            </friction>
          </surface>
        </collision>
        <visual name='Wall_37_Visual'>
          <pose>0 0 1.25 0 -0 0</pose>
          <geometry>
            <box>
              <size>1.95373 0.15 2.5</size>
            </box>
          </geometry>
          <material>
            <script>
              <uri>file://media/materials/scripts/gazebo.material</uri>
              <name>Gazebo/Grey</name>
            </script>
            <ambient>1 1 1 1</ambient>
          </material>
          <meta>
            <layer>0</layer>
          </meta>
        </visual>
        <pose>-3.94087 1.04541 0 0 -0 0.362199</pose>
        <self_collide>0</self_collide>
        <enable_wind>0</enable_wind>
        <kinematic>0</kinematic>
      </link>
      <link name='Wall_38'>
        <collision name='Wall_38_Collision'>
          <geometry>
            <box>
              <size>4 0.15 2.5</size>
            </box>
          </geometry>
          <pose>0 0 1.25 0 -0 0</pose>
          <max_contacts>10</max_contacts>
          <surface>
            <contact>
              <ode/>
            </contact>
            <bounce/>
            <friction>
              <torsional>
                <ode/>
              </torsional>
              <ode/>
            </friction>
          </surface>
        </collision>
        <visual name='Wall_38_Visual'>
          <pose>0 0 1.25 0 -0 0</pose>
          <geometry>
            <box>
              <size>4 0.15 2.5</size>
            </box>
          </geometry>
          <material>
            <script>
              <uri>file://media/materials/scripts/gazebo.material</uri>
              <name>Gazebo/Grey</name>
            </script>
            <ambient>1 1 1 1</ambient>
          </material>
          <meta>
            <layer>0</layer>
          </meta>
        </visual>
        <pose>-1.17252 1.36496 0 0 -0 0</pose>
        <self_collide>0</self_collide>
        <enable_wind>0</enable_wind>
        <kinematic>0</kinematic>
      </link>
      <link name='Wall_4'>
        <collision name='Wall_4_Collision'>
          <geometry>
            <box>
              <size>5.486 0.15 2</size>
            </box>
          </geometry>
          <pose>0 0 1 0 -0 0</pose>
          <max_contacts>10</max_contacts>
          <surface>
            <contact>
              <ode/>
            </contact>
            <bounce/>
            <friction>
              <torsional>
                <ode/>
              </torsional>
              <ode/>
            </friction>
          </surface>
        </collision>
        <visual name='Wall_4_Visual'>
          <pose>0 0 1 0 -0 0</pose>
          <geometry>
            <box>
              <size>5.486 0.15 2</size>
            </box>
          </geometry>
          <material>
            <script>
              <uri>file://media/materials/scripts/gazebo.material</uri>
              <name>Gazebo/Grey</name>
            </script>
            <ambient>1 1 1 1</ambient>
          </material>
          <meta>
            <layer>0</layer>
          </meta>
        </visual>
        <pose>4.53412 4.91054 0 0 -0 3.14159</pose>
        <self_collide>0</self_collide>
        <enable_wind>0</enable_wind>
        <kinematic>0</kinematic>
      </link>
      <link name='Wall_6'>
        <collision name='Wall_6_Collision'>
          <geometry>
            <box>
              <size>1.674 0.15 2</size>
            </box>
          </geometry>
          <pose>0 0 1 0 -0 0</pose>
          <max_contacts>10</max_contacts>
          <surface>
            <contact>
              <ode/>
            </contact>
            <bounce/>
            <friction>
              <torsional>
                <ode/>
              </torsional>
              <ode/>
            </friction>
          </surface>
        </collision>
        <visual name='Wall_6_Visual'>
          <pose>0 0 1 0 -0 0</pose>
          <geometry>
            <box>
              <size>1.674 0.15 2</size>
            </box>
          </geometry>
          <material>
            <script>
              <uri>file://media/materials/scripts/gazebo.material</uri>
              <name>Gazebo/Grey</name>
            </script>
            <ambient>1 1 1 1</ambient>
          </material>
          <meta>
            <layer>0</layer>
          </meta>
        </visual>
        <pose>6.44012 0.184538 0 0 -0 3.14159</pose>
        <self_collide>0</self_collide>
        <enable_wind>0</enable_wind>
        <kinematic>0</kinematic>
      </link>
      <link name='Wall_7'>
        <collision name='Wall_7_Collision'>
          <geometry>
            <box>
              <size>0.406 0.15 2</size>
            </box>
          </geometry>
          <pose>0 0 1 0 -0 0</pose>
          <max_contacts>10</max_contacts>
          <surface>
            <contact>
              <ode/>
            </contact>
            <bounce/>
            <friction>
              <torsional>
                <ode/>
              </torsional>
              <ode/>
            </friction>
          </surface>
        </collision>
        <visual name='Wall_7_Visual'>
          <pose>0 0 1 0 -0 0</pose>
          <geometry>
            <box>
              <size>0.406 0.15 2</size>
            </box>
          </geometry>
          <material>
            <script>
              <uri>file://media/materials/scripts/gazebo.material</uri>
              <name>Gazebo/Grey</name>
            </script>
            <ambient>1 1 1 1</ambient>
          </material>
          <meta>
            <layer>0</layer>
          </meta>
        </visual>
        <pose>5.67812 0.056538 0 0 -0 -1.5708</pose>
        <self_collide>0</self_collide>
        <enable_wind>0</enable_wind>
        <kinematic>0</kinematic>
      </link>
      <link name='Wall_8'>
        <collision name='Wall_8_Collision'>
          <geometry>
            <box>
              <size>3.982 0.17 2</size>
            </box>
          </geometry>
          <pose>0 0 1 0 -0 0</pose>
          <max_contacts>10</max_contacts>
          <surface>
            <contact>
              <ode/>
            </contact>
            <bounce/>
            <friction>
              <torsional>
                <ode/>
              </torsional>
              <ode/>
            </friction>
          </surface>
        </collision>
        <visual name='Wall_8_Visual'>
          <pose>0 0 1 0 -0 0</pose>
          <geometry>
            <box>
              <size>3.982 0.17 2</size>
            </box>
          </geometry>
          <material>
            <script>
              <uri>file://media/materials/scripts/gazebo.material</uri>
              <name>Gazebo/Grey</name>
            </script>
            <ambient>1 1 1 1</ambient>
          </material>
          <meta>
            <layer>0</layer>
          </meta>
        </visual>
        <pose>3.77212 -0.071462 0 0 -0 3.14159</pose>
        <self_collide>0</self_collide>
        <enable_wind>0</enable_wind>
        <kinematic>0</kinematic>
      </link>
      <static>1</static>
    </model>
    <state world_name='default'>
      <sim_time>22 292000000</sim_time>
      <real_time>77 864142107</real_time>
      <wall_time>1635445696 365596678</wall_time>
      <iterations>22292</iterations>
      <model name='Basement'>
        <pose>-6.12947 -0.90241 0 0 -0 0</pose>
        <scale>1 1 1</scale>
        <link name='Wall_0'>
          <pose>1.07265 1.64513 0 0 -0 1.5708</pose>
          <velocity>0 0 0 0 -0 0</velocity>
          <acceleration>0 0 0 0 -0 0</acceleration>
          <wrench>0 0 0 0 -0 0</wrench>
        </link>
        <link name='Wall_10'>
          <pose>-0.48143 -3.39295 0 0 0 -1.58323</pose>
          <velocity>0 0 0 0 -0 0</velocity>
          <acceleration>0 0 0 0 -0 0</acceleration>
          <wrench>0 0 0 0 -0 0</wrench>
        </link>
        <link name='Wall_11'>
          <pose>-6.90643 -5.78195 0 0 -0 3.14159</pose>
          <velocity>0 0 0 0 -0 0</velocity>
          <acceleration>0 0 0 0 -0 0</acceleration>
          <wrench>0 0 0 0 -0 0</wrench>
        </link>
        <link name='Wall_12'>
          <pose>-13.3314 -3.60695 0 0 -0 1.5708</pose>
          <velocity>0 0 0 0 -0 0</velocity>
          <acceleration>0 0 0 0 -0 0</acceleration>
          <wrench>0 0 0 0 -0 0</wrench>
        </link>
        <link name='Wall_15'>
          <pose>-13.3314 1.24305 0 0 -0 1.5708</pose>
          <velocity>0 0 0 0 -0 0</velocity>
          <acceleration>0 0 0 0 -0 0</acceleration>
          <wrench>0 0 0 0 -0 0</wrench>
        </link>
        <link name='Wall_16'>
          <pose>-11.4764 3.92209 0 0 -0 0.002176</pose>
          <velocity>0 0 0 0 -0 0</velocity>
          <acceleration>0 0 0 0 -0 0</acceleration>
          <wrench>0 0 0 0 -0 0</wrench>
        </link>
        <link name='Wall_17'>
          <pose>-9.62135 3.18813 0 0 0 -1.5708</pose>
          <velocity>0 0 0 0 -0 0</velocity>
          <acceleration>0 0 0 0 -0 0</acceleration>
          <wrench>0 0 0 0 -0 0</wrench>
        </link>
        <link name='Wall_21'>
          <pose>-7.94635 2.45013 0 0 -0 0</pose>
          <velocity>0 0 0 0 -0 0</velocity>
          <acceleration>0 0 0 0 -0 0</acceleration>
          <wrench>0 0 0 0 -0 0</wrench>
        </link>
        <link name='Wall_28'>
          <pose>-4.26335 2.21613 0 0 0 -1.5708</pose>
          <velocity>0 0 0 0 -0 0</velocity>
          <acceleration>0 0 0 0 -0 0</acceleration>
          <wrench>0 0 0 0 -0 0</wrench>
        </link>
        <link name='Wall_30'>
          <pose>-5.34635 2.45013 0 0 -0 0</pose>
          <velocity>0 0 0 0 -0 0</velocity>
          <acceleration>0 0 0 0 -0 0</acceleration>
          <wrench>0 0 0 0 -0 0</wrench>
        </link>
        <link name='Wall_32'>
          <pose>-5.37699 -0.337445 0 0 0 -1.5708</pose>
          <velocity>0 0 0 0 -0 0</velocity>
          <acceleration>0 0 0 0 -0 0</acceleration>
          <wrench>0 0 0 0 -0 0</wrench>
        </link>
        <link name='Wall_33'>
          <pose>-7.80199 -1.13745 0 0 -0 3.14159</pose>
          <velocity>0 0 0 0 -0 0</velocity>
          <acceleration>0 0 0 0 -0 0</acceleration>
          <wrench>0 0 0 0 -0 0</wrench>
        </link>
        <link name='Wall_34'>
          <pose>-10.5703 -0.657004 0 0 -0 2.19129</pose>
          <velocity>0 0 0 0 -0 0</velocity>
          <acceleration>0 0 0 0 -0 0</acceleration>
          <wrench>0 0 0 0 -0 0</wrench>
        </link>
        <link name='Wall_35'>
          <pose>-11.2137 -0.176563 0 0 -0 3.14159</pose>
          <velocity>0 0 0 0 -0 0</velocity>
          <acceleration>0 0 0 0 -0 0</acceleration>
          <wrench>0 0 0 0 -0 0</wrench>
        </link>
        <link name='Wall_37'>
          <pose>-10.0703 0.143 0 0 -0 0.362199</pose>
          <velocity>0 0 0 0 -0 0</velocity>
          <acceleration>0 0 0 0 -0 0</acceleration>
          <wrench>0 0 0 0 -0 0</wrench>
        </link>
        <link name='Wall_38'>
          <pose>-7.30199 0.46255 0 0 -0 0</pose>
          <velocity>0 0 0 0 -0 0</velocity>
          <acceleration>0 0 0 0 -0 0</acceleration>
          <wrench>0 0 0 0 -0 0</wrench>
        </link>
        <link name='Wall_4'>
          <pose>-1.59535 4.00813 0 0 -0 3.14159</pose>
          <velocity>0 0 0 0 -0 0</velocity>
          <acceleration>0 0 0 0 -0 0</acceleration>
          <wrench>0 0 0 0 -0 0</wrench>
        </link>
        <link name='Wall_6'>
          <pose>0.31065 -0.717872 0 0 -0 3.14159</pose>
          <velocity>0 0 0 0 -0 0</velocity>
          <acceleration>0 0 0 0 -0 0</acceleration>
          <wrench>0 0 0 0 -0 0</wrench>
        </link>
        <link name='Wall_7'>
          <pose>-0.45135 -0.845872 0 0 0 -1.5708</pose>
          <velocity>0 0 0 0 -0 0</velocity>
          <acceleration>0 0 0 0 -0 0</acceleration>
          <wrench>0 0 0 0 -0 0</wrench>
        </link>
        <link name='Wall_8'>
          <pose>-2.35735 -0.973872 0 0 -0 3.14159</pose>
          <velocity>0 0 0 0 -0 0</velocity>
          <acceleration>0 0 0 0 -0 0</acceleration>
          <wrench>0 0 0 0 -0 0</wrench>
        </link>
      </model>
      <model name='ground_plane'>
        <pose>0 0 0 0 -0 0</pose>
        <scale>1 1 1</scale>
        <link name='link'>
          <pose>0 0 0 0 -0 0</pose>
          <velocity>0 0 0 0 -0 0</velocity>
          <acceleration>0 0 0 0 -0 0</acceleration>
          <wrench>0 0 0 0 -0 0</wrench>
        </link>
      </model>
      <model name='pluto.xacro'>
        <pose>-0.004035 -5.7e-05 0.007907 -1.6e-05 -0.006973 -3.14159</pose>
        <scale>1 1 1</scale>
        <link name='base_footprint'>
          <pose>-0.004035 -5.7e-05 0.007907 -1.6e-05 -0.006973 -3.14159</pose>
          <velocity>-0.000114 -2e-06 0.005014 -0.0003 0.000821 8.9e-05</velocity>
          <acceleration>0.040847 -0.003174 10.0278 2.54049 1.48948 -2.73763</acceleration>
          <wrench>0.171599 -0.013334 42.1267 0 -0 0</wrench>
        </link>
        <link name='caster_wheel'>
          <pose>-0.089005 -5.8e-05 0.0125 -2.2e-05 0.461711 3.14159</pose>
          <velocity>-9.7e-05 -5e-06 0.005182 0.000381 -0.007783 8.9e-05</velocity>
          <acceleration>0.032807 -0.042043 10.3647 0.763934 -0.000801 0.389079</acceleration>
          <wrench>0.164036 -0.210213 51.8233 0 -0 0</wrench>
        </link>
        <link name='head'>
          <pose>-0.01076 -6.6e-05 0.477965 -3.4e-05 -0.006968 -3.1393</pose>
          <velocity>-0.000293 -4.7e-05 0.004995 6.4e-05 -0.000253 0.000106</velocity>
          <acceleration>-0.355096 -0.111137 9.98977 0.127031 -0.495539 -0.000894</acceleration>
          <wrench>-0.355096 -0.111137 9.98977 0 -0 0</wrench>
        </link>
        <link name='left_forearm_bottom'>
          <pose>0.002887 -0.077576 0.272483 0.071309 1.52077 -2.98461</pose>
          <velocity>-7.1e-05 -0.003351 0.004906 -0.023967 -0.081595 -0.002211</velocity>
          <acceleration>-0.938575 -0.157493 9.7676 0.970457 -1.35012 0.636787</acceleration>
          <wrench>-0.469287 -0.078746 4.8838 0 -0 0</wrench>
        </link>
        <link name='left_forearm_top'>
          <pose>0.001455 -0.077803 0.24352 1.97643 1.52077 -2.98461</pose>
          <velocity>0.002294 -0.004043 0.004787 -0.011324 -0.079552 0.253196</velocity>
          <acceleration>-0.350517 -0.119017 9.72464 1.87465 1.50521 -0.013066</acceleration>
          <wrench>-0.140207 -0.047607 3.88985 0 -0 0</wrench>
        </link>
        <link name='left_index_bottom'>
          <pose>-0.001137 -0.065662 0.138598 -1.61747 1.13409 -0.290506</pose>
          <velocity>-0.07501 0.015166 0.009745 2.32594 0.110766 -2.82374</velocity>
          <acceleration>2.62265 -0.247141 9.7955 -1.49453 1.36844 -1.54336</acceleration>
          <wrench>0.052453 -0.004943 0.19591 0 -0 0</wrench>
        </link>
        <link name='left_index_top'>
          <pose>0.005682 -0.067749 0.120957 -2.28735 1.54075 -0.964539</pose>
          <velocity>-0.016916 0.002922 0.033643 0.009624 0.003064 0.251512</velocity>
          <acceleration>-5.70938 1.92802 6.61476 2.71286 -1.3481 3.0217</acceleration>
          <wrench>-0.114188 0.03856 0.132295 0 -0 0</wrench>
        </link>
        <link name='left_middle_bottom'>
          <pose>-0.004063 -0.074151 0.138774 -1.69904 1.4159 -0.374932</pose>
          <velocity>-0.072871 0.01446 0.011227 -0.109184 -0.466051 0.261084</velocity>
          <acceleration>2.60859 -0.243094 9.71218 1.65725 -0.555354 0.541795</acceleration>
          <wrench>0.052172 -0.004862 0.194244 0 -0 0</wrench>
        </link>
        <link name='left_middle_top'>
          <pose>-0.001169 -0.075504 0.118524 -2.27811 1.54043 -0.955286</pose>
          <velocity>-0.06305 0.012994 0.012744 0.009658 0.003035 0.251522</velocity>
          <acceleration>-2.42449 1.14291 8.91708 2.79217 -1.32942 3.02239</acceleration>
          <wrench>-0.04849 0.022858 0.178342 0 -0 0</wrench>
        </link>
        <link name='left_palm'>
          <pose>-0.001768 -0.078313 0.178351 -3.13739 1.55106 -1.8148</pose>
          <velocity>0.007601 -0.005597 0.004534 -2.62284 1.13051 -2.93099</velocity>
          <acceleration>0.954758 -0.033596 9.66491 -2.38661 -0.248149 2.57209</acceleration>
          <wrench>0.305523 -0.010751 3.09277 0 -0 0</wrench>
        </link>
        <link name='left_pinky_bottom'>
          <pose>-0.008177 -0.090385 0.139105 -1.72731 1.4439 -0.403485</pose>
          <velocity>-0.068788 0.013421 0.011085 1.98989 1.52892 0.092473</velocity>
          <acceleration>2.58498 -0.238558 9.61347 -0.260787 0.412623 -0.704294</acceleration>
          <wrench>0.0517 -0.004771 0.192269 0 -0 0</wrench>
        </link>
        <link name='left_pinky_top'>
          <pose>-0.006199 -0.090972 0.124747 -2.27738 1.5404 -0.954565</pose>
          <velocity>-0.180798 0.042153 -0.006098 0.009644 0.003037 0.251526</velocity>
          <acceleration>-2.30027 1.03003 9.74716 2.76233 -1.33633 3.02208</acceleration>
          <wrench>-0.046005 0.020601 0.194943 0 -0 0</wrench>
        </link>
        <link name='left_ring_bottom'>
          <pose>-0.00615 -0.082389 0.138942 -2.88912 1.55042 -1.56648</pose>
          <velocity>-0.070801 0.013933 0.011158 1.64261 0.159546 0.120355</velocity>
          <acceleration>2.59395 -0.240701 9.66738 2.63552 -1.50337 0.931258</acceleration>
          <wrench>0.051879 -0.004814 0.193348 0 -0 0</wrench>
        </link>
        <link name='left_ring_top'>
          <pose>-0.005615 -0.082705 0.119943 -2.27407 1.54028 -0.951246</pose>
          <velocity>-0.193144 0.045206 0.006714 0.009652 0.003027 0.251519</velocity>
          <acceleration>-0.457979 0.600973 10.3678 2.77768 -1.33127 3.02162</acceleration>
          <wrench>-0.00916 0.012019 0.207355 0 -0 0</wrench>
        </link>
        <link name='left_shoulder'>
          <pose>-0.001442 -0.055064 0.379897 -1.9e-05 0.040293 3.14159</pose>
          <velocity>-0.000209 -7e-06 0.004983 0.000423 -0.002868 -0.000858</velocity>
          <acceleration>-0.175996 -0.028831 9.96575 -2.27506 -0.83952 1.62402</acceleration>
          <wrench>-0.527987 -0.086493 29.8973 0 -0 0</wrench>
        </link>
        <link name='left_thumb_bottom'>
          <pose>-0.011496 -0.063818 0.160616 3.09806 1.10008 -0.265029</pose>
          <velocity>-0.031143 0.001553 0.031583 -2.1019 -1.14576 -2.97785</velocity>
          <acceleration>1.76835 -0.048488 9.26845 1.58394 -0.620839 0.234386</acceleration>
          <wrench>0.035367 -0.00097 0.185369 0 -0 0</wrench>
        </link>
        <link name='left_thumb_piece'>
          <pose>-0.000703 -0.065975 0.164107 1.55303 1.55106 -1.81478</pose>
          <velocity>-0.023648 0.002021 0.008771 -2.6229 1.13056 -2.92982</velocity>
          <acceleration>1.55276 -0.109886 9.72647 0.866153 1.05814 -2.6271</acceleration>
          <wrench>0.155276 -0.010989 0.972647 0 -0 0</wrench>
        </link>
        <link name='left_thumb_top'>
          <pose>-0.004342 -0.057995 0.149327 0.024456 -0.631142 2.90094</pose>
          <velocity>-0.08042 0.014515 0.006839 2.58351 -0.491934 -2.83728</velocity>
          <acceleration>-1.93233 0.7877 7.55782 -2.211 1.53479 2.0223</acceleration>
          <wrench>-0.038647 0.015754 0.151156 0 -0 0</wrench>
        </link>
        <link name='left_upper_arm_bottom'>
          <pose>-0.001443 -0.077564 0.379896 0.00011 0.040292 3.14159</pose>
          <velocity>-0.000365 -4.5e-05 0.004885 -0.030714 -0.002628 -0.00211</velocity>
          <acceleration>-0.482541 -0.103324 9.7682 2.72062 -1.31906 1.78997</acceleration>
          <wrench>-0.24127 -0.051662 4.8841 0 -0 0</wrench>
        </link>
        <link name='left_upper_arm_top'>
          <pose>-0.000184 -0.077567 0.348672 0.003566 0.040133 -3.05569</pose>
          <velocity>-0.000249 -0.000999 0.004916 -0.030773 -0.002368 -0.002492</velocity>
          <acceleration>-0.555316 -0.104973 9.81835 -0.792376 -1.30225 1.57418</acceleration>
          <wrench>-2.22126 -0.419893 39.2734 0 -0 0</wrench>
        </link>
        <link name='left_wheel'>
          <pose>0.06869 -0.114557 0.039798 -1.6e-05 0.025468 -3.14159</pose>
          <velocity>-5.5e-05 1.4e-05 0.004763 -0.000349 -0.001353 9.6e-05</velocity>
          <acceleration>0.141245 0.029148 9.52354 -0.685974 -0.522626 0.395418</acceleration>
          <wrench>1.41245 0.291476 95.2354 0 -0 0</wrench>
        </link>
        <link name='right_forearm_bottom'>
          <pose>-0.001252 0.07909 0.272412 0.409702 1.5325 0.121415</pose>
          <velocity>-0.018216 0.007014 0.005064 -0.096439 -0.382278 0.441772</velocity>
          <acceleration>0.035167 -0.317475 9.97881 2.70242 -0.936189 3.06801</acceleration>
          <wrench>0.017583 -0.158738 4.98941 0 -0 0</wrench>
        </link>
        <link name='right_forearm_top'>
          <pose>-0.00015 0.079224 0.243433 0.391476 1.5325 0.121386</pose>
          <velocity>-0.007217 0.004696 0.005462 -0.055504 -0.377114 -0.640876</velocity>
          <acceleration>-0.288113 -0.289465 9.95635 -2.81243 -0.859724 -2.86905</acceleration>
          <wrench>-0.115245 -0.115786 3.98254 0 -0 0</wrench>
        </link>
        <link name='right_index_bottom'>
          <pose>0.016551 0.076203 0.139148 -1.3662 1.39574 -1.63959</pose>
          <velocity>0.023505 -0.035985 0.011514 -2.40333 -1.46667 -0.49712</velocity>
          <acceleration>-1.47909 -0.531998 9.76278 1.94197 0.758938 2.0548</acceleration>
          <wrench>-0.029582 -0.01064 0.195256 0 -0 0</wrench>
        </link>
        <link name='right_index_top'>
          <pose>0.016054 0.071954 0.120609 0.621954 1.52724 0.352055</pose>
          <velocity>0.048545 0.03614 -0.005904 -0.079615 -0.370928 -0.641705</velocity>
          <acceleration>-0.175672 4.26346 8.90737 -1.06442 0.564103 -3.07872</acceleration>
          <wrench>-0.003513 0.085269 0.178147 0 -0 0</wrench>
        </link>
        <link name='right_middle_bottom'>
          <pose>0.007734 0.077871 0.138773 -1.31558 1.43017 -1.58834</pose>
          <velocity>0.024687 -0.030385 0.008569 -2.16459 -1.53285 -0.488363</velocity>
          <acceleration>-1.4806 -0.537388 9.85893 -1.52373 1.354 2.46366</acceleration>
          <wrench>-0.029612 -0.010748 0.197179 0 -0 0</wrench>
        </link>
        <link name='right_middle_top'>
          <pose>0.00749 0.075051 0.118467 0.630314 1.52697 0.360423</pose>
          <velocity>0.0544 0.05333 -0.003648 -0.079597 -0.370945 -0.641726</velocity>
          <acceleration>-0.595668 2.86005 9.73942 -1.05903 0.601303 -3.08195</acceleration>
          <wrench>-0.011913 0.057201 0.194788 0 -0 0</wrench>
        </link>
        <link name='right_palm'>
          <pose>0.002329 0.079527 0.178231 1.14546 1.48493 0.876501</pose>
          <velocity>0.017559 -0.000499 0.006367 -0.666566 -0.208097 -0.663207</velocity>
          <acceleration>-0.959515 -0.191508 9.92183 -1.72911 0.792565 2.1594</acceleration>
          <wrench>-0.307045 -0.061283 3.17499 0 -0 0</wrench>
        </link>
        <link name='right_pinky_bottom'>
          <pose>-0.008398 0.082342 0.13818 -1.50128 1.03659 -1.7813</pose>
          <velocity>0.027769 -0.020081 0.002235 -1.06282 1.30441 3.03749</velocity>
          <acceleration>-1.48434 -0.55363 10.0239 -0.712585 -1.44268 1.19557</acceleration>
          <wrench>-0.029687 -0.011073 0.200479 0 -0 0</wrench>
        </link>
        <link name='right_pinky_top'>
          <pose>-0.009687 0.075271 0.125575 0.631418 1.52694 0.361527</pose>
          <velocity>0.08276 0.163612 -0.108834 -0.079562 -0.370834 -0.641774</velocity>
          <acceleration>1.50439 9.13512 7.72579 -0.991231 0.282984 -3.07824</acceleration>
          <wrench>0.030088 0.182702 0.154516 0 -0 0</wrench>
        </link>
        <link name='right_ring_bottom'>
          <pose>-0.000453 0.08014 0.138472 1.25606 1.45629 0.987629</pose>
          <velocity>0.02625 -0.025152 0.005356 2.80291 0.635873 2.94954</velocity>
          <acceleration>-1.48501 -0.538196 9.9444 0.376588 1.43269 0.1177</acceleration>
          <wrench>-0.0297 -0.010764 0.198888 0 -0 0</wrench>
        </link>
        <link name='right_ring_top'>
          <pose>0.001066 0.082379 0.11965 0.63388 1.52686 0.363991</pose>
          <velocity>0.097818 0.204924 0.036947 -0.079525 -0.370723 -0.641776</velocity>
          <acceleration>-1.96808 -2.27309 12.8988 -0.918447 0.225039 -3.09028</acceleration>
          <wrench>-0.039362 -0.045462 0.257976 0 -0 0</wrench>
        </link>
        <link name='right_shoulder'>
          <pose>-0.001442 0.054937 0.379899 -1.7e-05 0.001776 -3.14159</pose>
          <velocity>2e-05 6.3e-05 0.005008 -0.000133 0.16726 1.6e-05</velocity>
          <acceleration>0.257967 0.111146 10.0146 2.88031 -0.393383 -2.90378</acceleration>
          <wrench>0.773901 0.333438 30.0437 0 -0 0</wrench>
        </link>
        <link name='right_thumb_bottom'>
          <pose>0.005545 0.081379 0.161468 -0.192144 1.11105 2.41687</pose>
          <velocity>0.052502 0.033167 0.010582 2.42943 -0.417299 -1.62641</velocity>
          <acceleration>-0.895409 -0.533765 9.80145 1.73871 0.208349 -2.51376</acceleration>
          <wrench>-0.017908 -0.010675 0.196029 0 -0 0</wrench>
        </link>
        <link name='right_thumb_piece'>
          <pose>0.014582 0.075157 0.165067 -1.7124 1.48493 0.876549</pose>
          <velocity>0.017406 -0.0174 0.011818 -0.387548 0.129352 0.544912</velocity>
          <acceleration>-1.14185 -0.295497 9.80311 -1.17309 -1.45888 2.00815</acceleration>
          <wrench>-0.114185 -0.02955 0.980311 0 -0 0</wrench>
        </link>
        <link name='right_thumb_top'>
          <pose>-0.00253 0.078692 0.149625 -2.67649 1.38037 -0.094293</pose>
          <velocity>-0.07739 0.137339 0.074367 -1.03269 -0.904197 0.451082</velocity>
          <acceleration>3.52534 -1.34187 9.89251 -0.719036 0.895586 -1.42358</acceleration>
          <wrench>0.070507 -0.026837 0.19785 0 -0 0</wrench>
        </link>
        <link name='right_upper_arm_bottom'>
          <pose>-0.001442 0.077437 0.379899 -0.015381 0.001777 -3.14158</pose>
          <velocity>-1e-06 6.5e-05 0.00501 0.065379 0.167189 0.001328</velocity>
          <acceleration>0.212815 0.115678 10.0188 0.572037 -0.205661 -0.040972</acceleration>
          <wrench>0.106407 0.057839 5.00939 0 -0 0</wrench>
        </link>
        <link name='right_upper_arm_top'>
          <pose>-0.001387 0.077917 0.348653 0.015251 0.002667 -0.287978</pose>
          <velocity>-0.005427 0.00204 0.005012 0.064455 0.160677 0.450406</velocity>
          <acceleration>-0.10045 -0.100521 9.97973 0.545858 -0.999455 -2.99339</acceleration>
          <wrench>-0.401801 -0.402084 39.9189 0 -0 0</wrench>
        </link>
        <link name='right_wheel'>
          <pose>0.068689 0.114443 0.039802 -1.6e-05 0.032327 -3.14159</pose>
          <velocity>-6.8e-05 7e-06 0.004739 -0.000191 -0.001707 -0.000234</velocity>
          <acceleration>0.06716 0.016194 9.47729 -0.385437 -0.876073 -0.263246</acceleration>
          <wrench>0.671603 0.16194 94.7729 0 -0 0</wrench>
        </link>
      </model>
      <light name='sun'>
        <pose>0 0 10 0 -0 0</pose>
      </light>
    </state>
    <gui fullscreen='0'>
      <camera name='user_camera'>
        <pose>-1.02963 -0.444485 19.0973 0 1.5658 -3.09899</pose>
        <view_controller>orbit</view_controller>
        <projection_type>perspective</projection_type>
      </camera>
    </gui>
  </world>
</sdf>
